{
  "version": 8,
  "blockIdVersion": 11,
  "anchorX": 0,
  "anchorY": 0,
  "anchorZ": 0,
  "blocks": [
    {
      "x": 0,
      "y": -1,
      "z": -2,
      "name": "Rock_Runic_Brick"
    },
    {
      "x": 0,
      "y": 0,
      "z": -2,
      "name": "Rock_Runic_Cobble"
    },
    {
      "x": 0,
      "y": 1,
      "z": -2,
      "name": "Rock_Runic_Cobble"
    },
    {
      "x": 0,
      "y": 2,
      "z": -2,
      "name": "Rock_Runic_Cobble"
    },
    {
      "x": 0,
      "y": 3,
      "z": -2,
      "name": "Rock_Runic_Cobble"
    },
    {
      "x": 0,
      "y": 4,
      "z": -2,
      "name": "Rock_Runic_Cobble_Half"
    },
    {
      "x": 0,
      "y": -1,
      "z": -1,
      "name": "Rock_Runic_Brick"
    },
    {
      "x": 0,
      "y": 0,
      "z": -1,
      "name": "Rock_Runic_Cobble"
    },
    {
      "x": 0,
      "y": 1,
      "z": -1,
      "name": "Rock_Runic_Cobble"
    },
    {
      "x": 0,
      "y": 2,
      "z": -1,
      "name": "Rock_Runic_Cobble"
    },
    {
      "x": 0,
      "y": 3,
      "z": -1,
      "name": "Rock_Runic_Cobble"
    },
    {
      "x": 0,
      "y": 4,
      "z": -1,
      "name": "Rock_Runic_Cobble_Half"
    },
    {
      "x": 0,
      "y": -1,
      "z": 0,
      "name": "Rock_Runic_Brick"
    },
    {
      "x": 0,
      "y": 0,
      "z": 0,
      "name": "Rock_Runic_Cobble"
    },
    {
      "x": 0,
      "y": 1,
      "z": 0,
      "name": "Empty"
    },
    {
      "x": 0,
      "y": 2,
      "z": 0,
      "name": "Empty"
    },
    {
      "x": 0,
      "y": 3,
      "z": 0,
      "name": "Empty"
    },
    {
      "x": 0,
      "y": 4,
      "z": 0,
      "name": "Empty"
    },
    {
      "x": 0,
      "y": -1,
      "z": 1,
      "name": "Rock_Runic_Brick"
    },
    {
      "x": 0,
      "y": 0,
      "z": 1,
      "name": "Empty"
    },
    {
      "x": 0,
      "y": 1,
      "z": 1,
      "name": "Empty"
    },
    {
      "x": 0,
      "y": 2,
      "z": 1,
      "name": "Empty"
    },
    {
      "x": 0,
      "y": 3,
      "z": 1,
      "name": "Empty"
    },
    {
      "x": 0,
      "y": 4,
      "z": 1,
      "name": "Empty"
    },
    {
      "x": 0,
      "y": -1,
      "z": 2,
      "name": "Rock_Runic_Brick"
    },
    {
      "x": 0,
      "y": 0,
      "z": 2,
      "name": "Rock_Runic_Cobble"
    },
    {
      "x": 0,
      "y": 1,
      "z": 2,
      "name": "Rock_Runic_Cobble"
    },
    {
      "x": 0,
      "y": 2,
      "z": 2,
      "name": "Rock_Runic_Cobble"
    },
    {
      "x": 0,
      "y": 3,
      "z": 2,
      "name": "Rock_Runic_Cobble"
    },
    {
      "x": 0,
      "y": 4,
      "z": 2,
      "name": "Rock_Runic_Cobble_Half"
    },
    {
      "x": 0,
      "y": -1,
      "z": 3,
      "name": "Rock_Runic_Brick"
    },
    {
      "x": 0,
      "y": 0,
      "z": 3,
      "name": "Rock_Runic_Cobble"
    },
    {
      "x": 0,
      "y": 1,
      "z": 3,
      "name": "Rock_Runic_Cobble"
    },
    {
      "x": 0,
      "y": 2,
      "z": 3,
      "name": "Rock_Runic_Cobble"
    },
    {
      "x": 0,
      "y": 3,
      "z": 3,
      "name": "Rock_Runic_Cobble"
    },
    {
      "x": 0,
      "y": 4,
      "z": 3,
      "name": "Rock_Runic_Cobble_Half"
    },
    {
      "x": 1,
      "y": -1,
      "z": -2,
      "name": "Rock_Runic_Brick"
    },
    {
      "x": 1,
      "y": 0,
      "z": -2,
      "name": "Rock_Runic_Cobble"
    },
    {
      "x": 1,
      "y": 1,
      "z": -2,
      "name": "Rock_Runic_Cobble"
    },
    {
      "x": 1,
      "y": 2,
      "z": -2,
      "name": "Rock_Runic_Cobble"
    },
    {
      "x": 1,
      "y": 3,
      "z": -2,
      "name": "Rock_Runic_Cobble"
    },
    {
      "x": 1,
      "y": 4,
      "z": -2,
      "name": "Rock_Runic_Cobble_Half"
    },
    {
      "x": 1,
      "y": -1,
      "z": -1,
      "name": "Rock_Runic_Brick"
    },
    {
      "x": 1,
      "y": 0,
      "z": -1,
      "name": "Rock_Runic_Cobble"
    },
    {
      "x": 1,
      "y": 1,
      "z": -1,
      "name": "Rock_Runic_Cobble"
    },
    {
      "x": 1,
      "y": 2,
      "z": -1,
      "name": "Rock_Runic_Cobble"
    },
    {
      "x": 1,
      "y": 3,
      "z": -1,
      "name": "Rock_Runic_Cobble"
    },
    {
      "x": 1,
      "y": 4,
      "z": -1,
      "name": "Rock_Runic_Cobble_Half"
    },
    {
      "x": 1,
      "y": -1,
      "z": 0,
      "name": "Rock_Runic_Brick"
    },
    {
      "x": 1,
      "y": 0,
      "z": 0,
      "name": "Empty"
    },
    {
      "x": 1,
      "y": 1,
      "z": 0,
      "name": "Empty"
    },
    {
      "x": 1,
      "y": 2,
      "z": 0,
      "name": "Empty"
    },
    {
      "x": 1,
      "y": 3,
      "z": 0,
      "name": "Empty"
    },
    {
      "x": 1,
      "y": 4,
      "z": 0,
      "name": "Empty"
    },
    {
      "x": 1,
      "y": -1,
      "z": 1,
      "name": "Rock_Runic_Brick"
    },
    {
      "x": 1,
      "y": 0,
      "z": 1,
      "name": "Empty"
    },
    {
      "x": 1,
      "y": 1,
      "z": 1,
      "name": "Empty"
    },
    {
      "x": 1,
      "y": 2,
      "z": 1,
      "name": "Empty"
    },
    {
      "x": 1,
      "y": 3,
      "z": 1,
      "name": "Empty"
    },
    {
      "x": 1,
      "y": 4,
      "z": 1,
      "name": "Empty"
    },
    {
      "x": 1,
      "y": -1,
      "z": 2,
      "name": "Rock_Runic_Brick"
    },
    {
      "x": 1,
      "y": 0,
      "z": 2,
      "name": "Rock_Runic_Cobble"
    },
    {
      "x": 1,
      "y": 1,
      "z": 2,
      "name": "Rock_Runic_Cobble"
    },
    {
      "x": 1,
      "y": 2,
      "z": 2,
      "name": "Rock_Runic_Cobble"
    },
    {
      "x": 1,
      "y": 3,
      "z": 2,
      "name": "Rock_Runic_Cobble"
    },
    {
      "x": 1,
      "y": 4,
      "z": 2,
      "name": "Rock_Runic_Cobble_Half"
    },
    {
      "x": 1,
      "y": -1,
      "z": 3,
      "name": "Rock_Runic_Brick"
    },
    {
      "x": 1,
      "y": 0,
      "z": 3,
      "name": "Rock_Runic_Cobble"
    },
    {
      "x": 1,
      "y": 1,
      "z": 3,
      "name": "Rock_Runic_Cobble"
    },
    {
      "x": 1,
      "y": 2,
      "z": 3,
      "name": "Rock_Runic_Cobble"
    },
    {
      "x": 1,
      "y": 3,
      "z": 3,
      "name": "Rock_Runic_Cobble"
    },
    {
      "x": 1,
      "y": 4,
      "z": 3,
      "name": "Rock_Runic_Cobble_Half"
    },
    {
      "x": 2,
      "y": -1,
      "z": -2,
      "name": "Rock_Runic_Brick"
    },
    {
      "x": 2,
      "y": 0,
      "z": -2,
      "name": "Rock_Runic_Cobble"
    },
    {
      "x": 2,
      "y": 1,
      "z": -2,
      "name": "Rock_Runic_Cobble"
    },
    {
      "x": 2,
      "y": 2,
      "z": -2,
      "name": "Rock_Runic_Cobble"
    },
    {
      "x": 2,
      "y": 3,
      "z": -2,
      "name": "Rock_Runic_Cobble"
    },
    {
      "x": 2,
      "y": 4,
      "z": -2,
      "name": "Rock_Runic_Cobble_Half"
    },
    {
      "x": 2,
      "y": -1,
      "z": -1,
      "name": "Rock_Runic_Brick"
    },
    {
      "x": 2,
      "y": 0,
      "z": -1,
      "name": "Rock_Runic_Cobble"
    },
    {
      "x": 2,
      "y": 1,
      "z": -1,
      "name": "Rock_Runic_Cobble"
    },
    {
      "x": 2,
      "y": 2,
      "z": -1,
      "name": "Rock_Runic_Cobble"
    },
    {
      "x": 2,
      "y": 3,
      "z": -1,
      "name": "Rock_Runic_Cobble"
    },
    {
      "x": 2,
      "y": 4,
      "z": -1,
      "name": "Rock_Runic_Cobble_Half"
    },
    {
      "x": 2,
      "y": -1,
      "z": 0,
      "name": "Rock_Runic_Brick"
    },
    {
      "x": 2,
      "y": 0,
      "z": 0,
      "name": "Empty"
    },
    {
      "x": 2,
      "y": 1,
      "z": 0,
      "name": "Empty"
    },
    {
      "x": 2,
      "y": 2,
      "z": 0,
      "name": "Empty"
    },
    {
      "x": 2,
      "y": 3,
      "z": 0,
      "name": "Empty"
    },
    {
      "x": 2,
      "y": 4,
      "z": 0,
      "name": "Empty"
    },
    {
      "x": 2,
      "y": -1,
      "z": 1,
      "name": "Rock_Runic_Brick"
    },
    {
      "x": 2,
      "y": 0,
      "z": 1,
      "name": "Empty"
    },
    {
      "x": 2,
      "y": 1,
      "z": 1,
      "name": "Empty"
    },
    {
      "x": 2,
      "y": 2,
      "z": 1,
      "name": "Empty"
    },
    {
      "x": 2,
      "y": 3,
      "z": 1,
      "name": "Empty"
    },
    {
      "x": 2,
      "y": 4,
      "z": 1,
      "name": "Empty"
    },
    {
      "x": 2,
      "y": -1,
      "z": 2,
      "name": "Rock_Runic_Brick"
    },
    {
      "x": 2,
      "y": 0,
      "z": 2,
      "name": "Rock_Runic_Cobble"
    },
    {
      "x": 2,
      "y": 1,
      "z": 2,
      "name": "Rock_Runic_Cobble"
    },
    {
      "x": 2,
      "y": 2,
      "z": 2,
      "name": "Rock_Runic_Cobble"
    },
    {
      "x": 2,
      "y": 3,
      "z": 2,
      "name": "Rock_Runic_Cobble"
    },
    {
      "x": 2,
      "y": 4,
      "z": 2,
      "name": "Rock_Runic_Cobble_Half"
    },
    {
      "x": 2,
      "y": -1,
      "z": 3,
      "name": "Rock_Runic_Brick"
    },
    {
      "x": 2,
      "y": 0,
      "z": 3,
      "name": "Rock_Runic_Cobble"
    },
    {
      "x": 2,
      "y": 1,
      "z": 3,
      "name": "Rock_Runic_Cobble"
    },
    {
      "x": 2,
      "y": 2,
      "z": 3,
      "name": "Rock_Runic_Cobble"
    },
    {
      "x": 2,
      "y": 3,
      "z": 3,
      "name": "Rock_Runic_Cobble"
    },
    {
      "x": 2,
      "y": 4,
      "z": 3,
      "name": "Rock_Runic_Cobble_Half"
    },
    {
      "x": 3,
      "y": -1,
      "z": -2,
      "name": "Rock_Runic_Brick"
    },
    {
      "x": 3,
      "y": 0,
      "z": -2,
      "name": "Rock_Runic_Cobble"
    },
    {
      "x": 3,
      "y": 1,
      "z": -2,
      "name": "Rock_Runic_Cobble"
    },
    {
      "x": 3,
      "y": 2,
      "z": -2,
      "name": "Rock_Runic_Cobble"
    },
    {
      "x": 3,
      "y": 3,
      "z": -2,
      "name": "Rock_Runic_Cobble"
    },
    {
      "x": 3,
      "y": 4,
      "z": -2,
      "name": "Rock_Runic_Cobble_Half"
    },
    {
      "x": 3,
      "y": -1,
      "z": -1,
      "name": "Rock_Runic_Brick"
    },
    {
      "x": 3,
      "y": 0,
      "z": -1,
      "name": "Rock_Runic_Cobble"
    },
    {
      "x": 3,
      "y": 1,
      "z": -1,
      "name": "Rock_Runic_Cobble"
    },
    {
      "x": 3,
      "y": 2,
      "z": -1,
      "name": "Rock_Runic_Cobble"
    },
    {
      "x": 3,
      "y": 3,
      "z": -1,
      "name": "Rock_Runic_Cobble"
    },
    {
      "x": 3,
      "y": 4,
      "z": -1,
      "name": "Rock_Runic_Cobble_Half"
    },
    {
      "x": 3,
      "y": -1,
      "z": 0,
      "name": "Rock_Runic_Brick"
    },
    {
      "x": 3,
      "y": 0,
      "z": 0,
      "name": "Empty"
    },
    {
      "x": 3,
      "y": 1,
      "z": 0,
      "name": "Empty"
    },
    {
      "x": 3,
      "y": 2,
      "z": 0,
      "name": "Empty"
    },
    {
      "x": 3,
      "y": 3,
      "z": 0,
      "name": "Empty"
    },
    {
      "x": 3,
      "y": 4,
      "z": 0,
      "name": "Empty"
    },
    {
      "x": 3,
      "y": -1,
      "z": 1,
      "name": "Rock_Runic_Brick"
    },
    {
      "x": 3,
      "y": 0,
      "z": 1,
      "name": "Empty"
    },
    {
      "x": 3,
      "y": 1,
      "z": 1,
      "name": "Empty"
    },
    {
      "x": 3,
      "y": 2,
      "z": 1,
      "name": "Empty"
    },
    {
      "x": 3,
      "y": 3,
      "z": 1,
      "name": "Empty"
    },
    {
      "x": 3,
      "y": 4,
      "z": 1,
      "name": "Empty"
    },
    {
      "x": 3,
      "y": -1,
      "z": 2,
      "name": "Rock_Runic_Brick"
    },
    {
      "x": 3,
      "y": 0,
      "z": 2,
      "name": "Rock_Runic_Cobble"
    },
    {
      "x": 3,
      "y": 1,
      "z": 2,
      "name": "Rock_Runic_Cobble"
    },
    {
      "x": 3,
      "y": 2,
      "z": 2,
      "name": "Rock_Runic_Cobble"
    },
    {
      "x": 3,
      "y": 3,
      "z": 2,
      "name": "Rock_Runic_Cobble"
    },
    {
      "x": 3,
      "y": 4,
      "z": 2,
      "name": "Rock_Runic_Cobble_Half"
    },
    {
      "x": 3,
      "y": -1,
      "z": 3,
      "name": "Rock_Runic_Brick"
    },
    {
      "x": 3,
      "y": 0,
      "z": 3,
      "name": "Rock_Runic_Cobble"
    },
    {
      "x": 3,
      "y": 1,
      "z": 3,
      "name": "Rock_Runic_Cobble"
    },
    {
      "x": 3,
      "y": 2,
      "z": 3,
      "name": "Rock_Runic_Cobble"
    },
    {
      "x": 3,
      "y": 3,
      "z": 3,
      "name": "Rock_Runic_Cobble"
    },
    {
      "x": 3,
      "y": 4,
      "z": 3,
      "name": "Rock_Runic_Cobble_Half"
    },
    {
      "x": 4,
      "y": -1,
      "z": -2,
      "name": "Rock_Runic_Brick"
    },
    {
      "x": 4,
      "y": 0,
      "z": -2,
      "name": "Rock_Runic_Cobble"
    },
    {
      "x": 4,
      "y": 1,
      "z": -2,
      "name": "Rock_Runic_Cobble"
    },
    {
      "x": 4,
      "y": 2,
      "z": -2,
      "name": "Rock_Runic_Cobble"
    },
    {
      "x": 4,
      "y": 3,
      "z": -2,
      "name": "Rock_Runic_Cobble"
    },
    {
      "x": 4,
      "y": 4,
      "z": -2,
      "name": "Rock_Runic_Cobble_Half"
    },
    {
      "x": 4,
      "y": -1,
      "z": -1,
      "name": "Rock_Runic_Brick"
    },
    {
      "x": 4,
      "y": 0,
      "z": -1,
      "name": "Rock_Runic_Cobble"
    },
    {
      "x": 4,
      "y": 1,
      "z": -1,
      "name": "Rock_Runic_Cobble"
    },
    {
      "x": 4,
      "y": 2,
      "z": -1,
      "name": "Rock_Runic_Cobble"
    },
    {
      "x": 4,
      "y": 3,
      "z": -1,
      "name": "Rock_Runic_Cobble"
    },
    {
      "x": 4,
      "y": 4,
      "z": -1,
      "name": "Rock_Runic_Cobble_Half"
    },
    {
      "x": 4,
      "y": -1,
      "z": 0,
      "name": "Rock_Runic_Brick"
    },
    {
      "x": 4,
      "y": 0,
      "z": 0,
      "name": "Rock_Runic_Cobble"
    },
    {
      "x": 4,
      "y": 1,
      "z": 0,
      "name": "Rock_Runic_Cobble"
    },
    {
      "x": 4,
      "y": 2,
      "z": 0,
      "name": "Rock_Runic_Cobble"
    },
    {
      "x": 4,
      "y": 3,
      "z": 0,
      "name": "Rock_Runic_Cobble"
    },
    {
      "x": 4,
      "y": 4,
      "z": 0,
      "name": "Rock_Runic_Cobble_Half"
    },
    {
      "x": 4,
      "y": -1,
      "z": 1,
      "name": "Rock_Runic_Brick"
    },
    {
      "x": 4,
      "y": 0,
      "z": 1,
      "name": "Rock_Runic_Cobble"
    },
    {
      "x": 4,
      "y": 1,
      "z": 1,
      "name": "Rock_Runic_Cobble"
    },
    {
      "x": 4,
      "y": 2,
      "z": 1,
      "name": "Rock_Runic_Cobble"
    },
    {
      "x": 4,
      "y": 3,
      "z": 1,
      "name": "Rock_Runic_Cobble"
    },
    {
      "x": 4,
      "y": 4,
      "z": 1,
      "name": "Rock_Runic_Cobble_Half"
    },
    {
      "x": 4,
      "y": -1,
      "z": 2,
      "name": "Rock_Runic_Brick"
    },
    {
      "x": 4,
      "y": 0,
      "z": 2,
      "name": "Rock_Runic_Cobble"
    },
    {
      "x": 4,
      "y": 1,
      "z": 2,
      "name": "Rock_Runic_Cobble"
    },
    {
      "x": 4,
      "y": 2,
      "z": 2,
      "name": "Rock_Runic_Cobble"
    },
    {
      "x": 4,
      "y": 3,
      "z": 2,
      "name": "Rock_Runic_Cobble"
    },
    {
      "x": 4,
      "y": 4,
      "z": 2,
      "name": "Rock_Runic_Cobble_Half"
    },
    {
      "x": 4,
      "y": -1,
      "z": 3,
      "name": "Rock_Runic_Brick"
    },
    {
      "x": 4,
      "y": 0,
      "z": 3,
      "name": "Rock_Runic_Cobble"
    },
    {
      "x": 4,
      "y": 1,
      "z": 3,
      "name": "Rock_Runic_Cobble"
    },
    {
      "x": 4,
      "y": 2,
      "z": 3,
      "name": "Rock_Runic_Cobble"
    },
    {
      "x": 4,
      "y": 3,
      "z": 3,
      "name": "Rock_Runic_Cobble"
    },
    {
      "x": 4,
      "y": 4,
      "z": 3,
      "name": "Rock_Runic_Cobble_Half"
    },
    {
      "x": 5,
      "y": -1,
      "z": -2,
      "name": "Rock_Runic_Brick"
    },
    {
      "x": 5,
      "y": 0,
      "z": -2,
      "name": "Rock_Runic_Cobble"
    },
    {
      "x": 5,
      "y": 1,
      "z": -2,
      "name": "Rock_Runic_Cobble"
    },
    {
      "x": 5,
      "y": 2,
      "z": -2,
      "name": "Rock_Runic_Cobble"
    },
    {
      "x": 5,
      "y": 3,
      "z": -2,
      "name": "Rock_Runic_Cobble"
    },
    {
      "x": 5,
      "y": 4,
      "z": -2,
      "name": "Rock_Runic_Cobble_Half"
    },
    {
      "x": 5,
      "y": -1,
      "z": -1,
      "name": "Rock_Runic_Brick"
    },
    {
      "x": 5,
      "y": 0,
      "z": -1,
      "name": "Rock_Runic_Cobble"
    },
    {
      "x": 5,
      "y": 1,
      "z": -1,
      "name": "Rock_Runic_Cobble"
    },
    {
      "x": 5,
      "y": 2,
      "z": -1,
      "name": "Rock_Runic_Cobble"
    },
    {
      "x": 5,
      "y": 3,
      "z": -1,
      "name": "Rock_Runic_Cobble"
    },
    {
      "x": 5,
      "y": 4,
      "z": -1,
      "name": "Rock_Runic_Cobble_Half"
    },
    {
      "x": 5,
      "y": -1,
      "z": 0,
      "name": "Rock_Runic_Brick"
    },
    {
      "x": 5,
      "y": 0,
      "z": 0,
      "name": "Rock_Runic_Cobble"
    },
    {
      "x": 5,
      "y": 1,
      "z": 0,
      "name": "Rock_Runic_Cobble"
    },
    {
      "x": 5,
      "y": 2,
      "z": 0,
      "name": "Rock_Runic_Cobble"
    },
    {
      "x": 5,
      "y": 3,
      "z": 0,
      "name": "Rock_Runic_Cobble"
    },
    {
      "x": 5,
      "y": 4,
      "z": 0,
      "name": "Rock_Runic_Cobble_Half"
    },
    {
      "x": 5,
      "y": -1,
      "z": 1,
      "name": "Rock_Runic_Brick"
    },
    {
      "x": 5,
      "y": 0,
      "z": 1,
      "name": "Rock_Runic_Cobble"
    },
    {
      "x": 5,
      "y": 1,
      "z": 1,
      "name": "Rock_Runic_Cobble"
    },
    {
      "x": 5,
      "y": 2,
      "z": 1,
      "name": "Rock_Runic_Cobble"
    },
    {
      "x": 5,
      "y": 3,
      "z": 1,
      "name": "Rock_Runic_Cobble"
    },
    {
      "x": 5,
      "y": 4,
      "z": 1,
      "name": "Rock_Runic_Cobble_Half"
    },
    {
      "x": 5,
      "y": -1,
      "z": 2,
      "name": "Rock_Runic_Brick"
    },
    {
      "x": 5,
      "y": 0,
      "z": 2,
      "name": "Rock_Runic_Cobble"
    },
    {
      "x": 5,
      "y": 1,
      "z": 2,
      "name": "Rock_Runic_Cobble"
    },
    {
      "x": 5,
      "y": 2,
      "z": 2,
      "name": "Rock_Runic_Cobble"
    },
    {
      "x": 5,
      "y": 3,
      "z": 2,
      "name": "Rock_Runic_Cobble"
    },
    {
      "x": 5,
      "y": 4,
      "z": 2,
      "name": "Rock_Runic_Cobble_Half"
    },
    {
      "x": 5,
      "y": -1,
      "z": 3,
      "name": "Rock_Runic_Brick"
    },
    {
      "x": 5,
      "y": 0,
      "z": 3,
      "name": "Rock_Runic_Cobble"
    },
    {
      "x": 5,
      "y": 1,
      "z": 3,
      "name": "Rock_Runic_Cobble"
    },
    {
      "x": 5,
      "y": 2,
      "z": 3,
      "name": "Rock_Runic_Cobble"
    },
    {
      "x": 5,
      "y": 3,
      "z": 3,
      "name": "Rock_Runic_Cobble"
    },
    {
      "x": 5,
      "y": 4,
      "z": 3,
      "name": "Rock_Runic_Cobble_Half"
    }
  ]
}