{
  "version": 8,
  "blockIdVersion": 11,
  "anchorX": 0,
  "anchorY": 0,
  "anchorZ": 0,
  "blocks": [
    {
      "x": -18,
      "y": 0,
      "z": -15,
      "name": "Soil_Grass"
    },
    {
      "x": -18,
      "y": 0,
      "z": -14,
      "name": "Soil_Grass"
    },
    {
      "x": -18,
      "y": 0,
      "z": -13,
      "name": "Soil_Grass"
    },
    {
      "x": -18,
      "y": 0,
      "z": -12,
      "name": "Soil_Dirt"
    },
    {
      "x": -18,
      "y": 1,
      "z": -12,
      "name": "Rock_Bedrock"
    },
    {
      "x": -18,
      "y": 2,
      "z": -12,
      "name": "Rock_Bedrock"
    },
    {
      "x": -18,
      "y": 3,
      "z": -12,
      "name": "Rock_Bedrock"
    },
    {
      "x": -18,
      "y": 4,
      "z": -12,
      "name": "Rock_Bedrock"
    },
    {
      "x": -18,
      "y": 5,
      "z": -12,
      "name": "Rock_Bedrock"
    },
    {
      "x": -18,
      "y": 0,
      "z": -11,
      "name": "Soil_Dirt"
    },
    {
      "x": -18,
      "y": 1,
      "z": -11,
      "name": "Rock_Bedrock"
    },
    {
      "x": -18,
      "y": 2,
      "z": -11,
      "name": "Rock_Bedrock"
    },
    {
      "x": -18,
      "y": 3,
      "z": -11,
      "name": "Rock_Bedrock"
    },
    {
      "x": -18,
      "y": 4,
      "z": -11,
      "name": "Rock_Bedrock"
    },
    {
      "x": -18,
      "y": 5,
      "z": -11,
      "name": "Rock_Bedrock"
    },
    {
      "x": -18,
      "y": 0,
      "z": -10,
      "name": "Soil_Grass"
    },
    {
      "x": -18,
      "y": 0,
      "z": -9,
      "name": "Soil_Grass"
    },
    {
      "x": -18,
      "y": 0,
      "z": -8,
      "name": "Soil_Grass"
    },
    {
      "x": -18,
      "y": 0,
      "z": -7,
      "name": "Soil_Grass"
    },
    {
      "x": -18,
      "y": 0,
      "z": -6,
      "name": "Soil_Grass"
    },
    {
      "x": -18,
      "y": 0,
      "z": -5,
      "name": "Soil_Grass"
    },
    {
      "x": -18,
      "y": 0,
      "z": -4,
      "name": "Soil_Grass"
    },
    {
      "x": -18,
      "y": 0,
      "z": -3,
      "name": "Soil_Grass"
    },
    {
      "x": -18,
      "y": 0,
      "z": -2,
      "name": "Soil_Grass"
    },
    {
      "x": -18,
      "y": 0,
      "z": -1,
      "name": "Soil_Grass"
    },
    {
      "x": -18,
      "y": 0,
      "z": 0,
      "name": "Soil_Grass"
    },
    {
      "x": -18,
      "y": 0,
      "z": 1,
      "name": "Soil_Grass"
    },
    {
      "x": -18,
      "y": 0,
      "z": 2,
      "name": "Soil_Grass"
    },
    {
      "x": -18,
      "y": 0,
      "z": 3,
      "name": "Soil_Grass"
    },
    {
      "x": -18,
      "y": 0,
      "z": 4,
      "name": "Soil_Grass"
    },
    {
      "x": -18,
      "y": 0,
      "z": 5,
      "name": "Soil_Grass"
    },
    {
      "x": -18,
      "y": 0,
      "z": 6,
      "name": "Soil_Grass"
    },
    {
      "x": -18,
      "y": 0,
      "z": 7,
      "name": "Soil_Grass"
    },
    {
      "x": -18,
      "y": 0,
      "z": 8,
      "name": "Soil_Grass"
    },
    {
      "x": -18,
      "y": 0,
      "z": 9,
      "name": "Soil_Grass"
    },
    {
      "x": -18,
      "y": 0,
      "z": 10,
      "name": "Soil_Grass"
    },
    {
      "x": -18,
      "y": 0,
      "z": 11,
      "name": "Soil_Grass"
    },
    {
      "x": -18,
      "y": 0,
      "z": 12,
      "name": "Soil_Grass"
    },
    {
      "x": -18,
      "y": 0,
      "z": 13,
      "name": "Soil_Grass"
    },
    {
      "x": -18,
      "y": 0,
      "z": 14,
      "name": "Soil_Grass"
    },
    {
      "x": -18,
      "y": 0,
      "z": 15,
      "name": "Soil_Grass"
    },
    {
      "x": -18,
      "y": 0,
      "z": 16,
      "name": "Soil_Grass"
    },
    {
      "x": -17,
      "y": 0,
      "z": -15,
      "name": "Soil_Grass"
    },
    {
      "x": -17,
      "y": 0,
      "z": -14,
      "name": "Rock_Runic_Brick",
      "rotation": 1
    },
    {
      "x": -17,
      "y": 1,
      "z": -14,
      "name": "Rock_Runic_Cobble",
      "rotation": 1
    },
    {
      "x": -17,
      "y": 2,
      "z": -14,
      "name": "Rock_Runic_Cobble",
      "rotation": 1
    },
    {
      "x": -17,
      "y": 3,
      "z": -14,
      "name": "Rock_Runic_Cobble",
      "rotation": 1
    },
    {
      "x": -17,
      "y": 4,
      "z": -14,
      "name": "Rock_Runic_Cobble",
      "rotation": 1
    },
    {
      "x": -17,
      "y": 5,
      "z": -14,
      "name": "Rock_Runic_Cobble_Half",
      "rotation": 1
    },
    {
      "x": -17,
      "y": 0,
      "z": -13,
      "name": "Rock_Runic_Brick",
      "rotation": 1
    },
    {
      "x": -17,
      "y": 1,
      "z": -13,
      "name": "Rock_Runic_Cobble",
      "rotation": 1
    },
    {
      "x": -17,
      "y": 2,
      "z": -13,
      "name": "Rock_Runic_Cobble",
      "rotation": 1
    },
    {
      "x": -17,
      "y": 3,
      "z": -13,
      "name": "Rock_Runic_Cobble",
      "rotation": 1
    },
    {
      "x": -17,
      "y": 4,
      "z": -13,
      "name": "Rock_Runic_Cobble",
      "rotation": 1
    },
    {
      "x": -17,
      "y": 5,
      "z": -13,
      "name": "Rock_Runic_Cobble_Half",
      "rotation": 1
    },
    {
      "x": -17,
      "y": 0,
      "z": -12,
      "name": "Rock_Runic_Brick",
      "rotation": 1
    },
    {
      "x": -17,
      "y": 0,
      "z": -11,
      "name": "Rock_Runic_Brick",
      "rotation": 1
    },
    {
      "x": -17,
      "y": 0,
      "z": -10,
      "name": "Rock_Runic_Brick",
      "rotation": 1
    },
    {
      "x": -17,
      "y": 1,
      "z": -10,
      "name": "Rock_Runic_Cobble",
      "rotation": 1
    },
    {
      "x": -17,
      "y": 2,
      "z": -10,
      "name": "Rock_Runic_Cobble",
      "rotation": 1
    },
    {
      "x": -17,
      "y": 3,
      "z": -10,
      "name": "Rock_Runic_Cobble",
      "rotation": 1
    },
    {
      "x": -17,
      "y": 4,
      "z": -10,
      "name": "Rock_Runic_Cobble",
      "rotation": 1
    },
    {
      "x": -17,
      "y": 5,
      "z": -10,
      "name": "Rock_Runic_Cobble_Half",
      "rotation": 1
    },
    {
      "x": -17,
      "y": 0,
      "z": -9,
      "name": "Rock_Runic_Brick",
      "rotation": 1
    },
    {
      "x": -17,
      "y": 1,
      "z": -9,
      "name": "Rock_Runic_Cobble",
      "rotation": 1
    },
    {
      "x": -17,
      "y": 2,
      "z": -9,
      "name": "Rock_Runic_Cobble",
      "rotation": 1
    },
    {
      "x": -17,
      "y": 3,
      "z": -9,
      "name": "Rock_Runic_Cobble",
      "rotation": 1
    },
    {
      "x": -17,
      "y": 4,
      "z": -9,
      "name": "Rock_Runic_Cobble",
      "rotation": 1
    },
    {
      "x": -17,
      "y": 5,
      "z": -9,
      "name": "Rock_Runic_Cobble_Half",
      "rotation": 1
    },
    {
      "x": -17,
      "y": 0,
      "z": -8,
      "name": "Rock_Runic_Brick",
      "rotation": 2
    },
    {
      "x": -17,
      "y": 1,
      "z": -8,
      "name": "Rock_Runic_Cobble",
      "rotation": 2
    },
    {
      "x": -17,
      "y": 2,
      "z": -8,
      "name": "Rock_Runic_Cobble",
      "rotation": 2
    },
    {
      "x": -17,
      "y": 3,
      "z": -8,
      "name": "Rock_Runic_Cobble",
      "rotation": 2
    },
    {
      "x": -17,
      "y": 4,
      "z": -8,
      "name": "Rock_Runic_Cobble",
      "rotation": 2
    },
    {
      "x": -17,
      "y": 5,
      "z": -8,
      "name": "Rock_Runic_Cobble_Half",
      "rotation": 2
    },
    {
      "x": -17,
      "y": 0,
      "z": -7,
      "name": "Rock_Runic_Brick",
      "rotation": 2
    },
    {
      "x": -17,
      "y": 1,
      "z": -7,
      "name": "Rock_Runic_Cobble",
      "rotation": 2
    },
    {
      "x": -17,
      "y": 2,
      "z": -7,
      "name": "Rock_Runic_Cobble",
      "rotation": 2
    },
    {
      "x": -17,
      "y": 3,
      "z": -7,
      "name": "Rock_Runic_Cobble",
      "rotation": 2
    },
    {
      "x": -17,
      "y": 4,
      "z": -7,
      "name": "Rock_Runic_Cobble",
      "rotation": 2
    },
    {
      "x": -17,
      "y": 5,
      "z": -7,
      "name": "Rock_Runic_Cobble_Half",
      "rotation": 2
    },
    {
      "x": -17,
      "y": 0,
      "z": -6,
      "name": "Rock_Runic_Brick",
      "rotation": 2
    },
    {
      "x": -17,
      "y": 1,
      "z": -6,
      "name": "Rock_Runic_Cobble",
      "rotation": 2
    },
    {
      "x": -17,
      "y": 2,
      "z": -6,
      "name": "Rock_Runic_Cobble",
      "rotation": 2
    },
    {
      "x": -17,
      "y": 3,
      "z": -6,
      "name": "Rock_Runic_Cobble",
      "rotation": 2
    },
    {
      "x": -17,
      "y": 4,
      "z": -6,
      "name": "Rock_Runic_Cobble",
      "rotation": 2
    },
    {
      "x": -17,
      "y": 5,
      "z": -6,
      "name": "Rock_Runic_Cobble_Half",
      "rotation": 2
    },
    {
      "x": -17,
      "y": 0,
      "z": -5,
      "name": "Rock_Runic_Brick",
      "rotation": 2
    },
    {
      "x": -17,
      "y": 1,
      "z": -5,
      "name": "Rock_Runic_Cobble",
      "rotation": 2
    },
    {
      "x": -17,
      "y": 2,
      "z": -5,
      "name": "Rock_Runic_Cobble",
      "rotation": 2
    },
    {
      "x": -17,
      "y": 3,
      "z": -5,
      "name": "Rock_Runic_Cobble",
      "rotation": 2
    },
    {
      "x": -17,
      "y": 4,
      "z": -5,
      "name": "Rock_Runic_Cobble",
      "rotation": 2
    },
    {
      "x": -17,
      "y": 5,
      "z": -5,
      "name": "Rock_Runic_Cobble_Half",
      "rotation": 2
    },
    {
      "x": -17,
      "y": 0,
      "z": -4,
      "name": "Rock_Runic_Brick",
      "rotation": 2
    },
    {
      "x": -17,
      "y": 1,
      "z": -4,
      "name": "Rock_Runic_Cobble",
      "rotation": 2
    },
    {
      "x": -17,
      "y": 2,
      "z": -4,
      "name": "Rock_Runic_Cobble",
      "rotation": 2
    },
    {
      "x": -17,
      "y": 3,
      "z": -4,
      "name": "Rock_Runic_Cobble",
      "rotation": 2
    },
    {
      "x": -17,
      "y": 4,
      "z": -4,
      "name": "Rock_Runic_Cobble",
      "rotation": 2
    },
    {
      "x": -17,
      "y": 5,
      "z": -4,
      "name": "Rock_Runic_Cobble_Half",
      "rotation": 2
    },
    {
      "x": -17,
      "y": 0,
      "z": -3,
      "name": "Rock_Runic_Brick",
      "rotation": 2
    },
    {
      "x": -17,
      "y": 1,
      "z": -3,
      "name": "Rock_Runic_Cobble",
      "rotation": 2
    },
    {
      "x": -17,
      "y": 2,
      "z": -3,
      "name": "Rock_Runic_Cobble",
      "rotation": 2
    },
    {
      "x": -17,
      "y": 3,
      "z": -3,
      "name": "Rock_Runic_Cobble",
      "rotation": 2
    },
    {
      "x": -17,
      "y": 4,
      "z": -3,
      "name": "Rock_Runic_Cobble",
      "rotation": 2
    },
    {
      "x": -17,
      "y": 5,
      "z": -3,
      "name": "Rock_Runic_Cobble_Half",
      "rotation": 2
    },
    {
      "x": -17,
      "y": 0,
      "z": -2,
      "name": "Rock_Runic_Brick"
    },
    {
      "x": -17,
      "y": 1,
      "z": -2,
      "name": "Rock_Runic_Cobble"
    },
    {
      "x": -17,
      "y": 2,
      "z": -2,
      "name": "Rock_Runic_Cobble"
    },
    {
      "x": -17,
      "y": 3,
      "z": -2,
      "name": "Rock_Runic_Cobble"
    },
    {
      "x": -17,
      "y": 4,
      "z": -2,
      "name": "Rock_Runic_Cobble"
    },
    {
      "x": -17,
      "y": 5,
      "z": -2,
      "name": "Rock_Runic_Cobble_Half"
    },
    {
      "x": -17,
      "y": 0,
      "z": -1,
      "name": "Rock_Runic_Brick"
    },
    {
      "x": -17,
      "y": 1,
      "z": -1,
      "name": "Rock_Runic_Cobble"
    },
    {
      "x": -17,
      "y": 2,
      "z": -1,
      "name": "Rock_Runic_Cobble"
    },
    {
      "x": -17,
      "y": 3,
      "z": -1,
      "name": "Rock_Runic_Cobble"
    },
    {
      "x": -17,
      "y": 4,
      "z": -1,
      "name": "Rock_Runic_Cobble"
    },
    {
      "x": -17,
      "y": 5,
      "z": -1,
      "name": "Rock_Runic_Cobble_Half"
    },
    {
      "x": -17,
      "y": 0,
      "z": 0,
      "name": "Rock_Runic_Brick"
    },
    {
      "x": -17,
      "y": 0,
      "z": 1,
      "name": "Rock_Runic_Brick"
    },
    {
      "x": -17,
      "y": 0,
      "z": 2,
      "name": "Rock_Runic_Brick"
    },
    {
      "x": -17,
      "y": 1,
      "z": 2,
      "name": "Rock_Runic_Cobble"
    },
    {
      "x": -17,
      "y": 2,
      "z": 2,
      "name": "Rock_Runic_Cobble"
    },
    {
      "x": -17,
      "y": 3,
      "z": 2,
      "name": "Rock_Runic_Cobble"
    },
    {
      "x": -17,
      "y": 4,
      "z": 2,
      "name": "Rock_Runic_Cobble"
    },
    {
      "x": -17,
      "y": 5,
      "z": 2,
      "name": "Rock_Runic_Cobble_Half"
    },
    {
      "x": -17,
      "y": 0,
      "z": 3,
      "name": "Rock_Runic_Brick"
    },
    {
      "x": -17,
      "y": 1,
      "z": 3,
      "name": "Rock_Runic_Cobble"
    },
    {
      "x": -17,
      "y": 2,
      "z": 3,
      "name": "Rock_Runic_Cobble"
    },
    {
      "x": -17,
      "y": 3,
      "z": 3,
      "name": "Rock_Runic_Cobble"
    },
    {
      "x": -17,
      "y": 4,
      "z": 3,
      "name": "Rock_Runic_Cobble"
    },
    {
      "x": -17,
      "y": 5,
      "z": 3,
      "name": "Rock_Runic_Cobble_Half"
    },
    {
      "x": -17,
      "y": 0,
      "z": 4,
      "name": "Rock_Runic_Brick",
      "rotation": 1
    },
    {
      "x": -17,
      "y": 1,
      "z": 4,
      "name": "Rock_Runic_Cobble",
      "rotation": 1
    },
    {
      "x": -17,
      "y": 2,
      "z": 4,
      "name": "Rock_Runic_Cobble",
      "rotation": 1
    },
    {
      "x": -17,
      "y": 3,
      "z": 4,
      "name": "Rock_Runic_Cobble",
      "rotation": 1
    },
    {
      "x": -17,
      "y": 4,
      "z": 4,
      "name": "Rock_Runic_Cobble",
      "rotation": 1
    },
    {
      "x": -17,
      "y": 5,
      "z": 4,
      "name": "Rock_Runic_Cobble_Half",
      "rotation": 1
    },
    {
      "x": -17,
      "y": 0,
      "z": 5,
      "name": "Rock_Runic_Brick",
      "rotation": 1
    },
    {
      "x": -17,
      "y": 1,
      "z": 5,
      "name": "Rock_Runic_Cobble",
      "rotation": 1
    },
    {
      "x": -17,
      "y": 2,
      "z": 5,
      "name": "Rock_Runic_Cobble",
      "rotation": 1
    },
    {
      "x": -17,
      "y": 3,
      "z": 5,
      "name": "Rock_Runic_Cobble",
      "rotation": 1
    },
    {
      "x": -17,
      "y": 4,
      "z": 5,
      "name": "Rock_Runic_Cobble",
      "rotation": 1
    },
    {
      "x": -17,
      "y": 5,
      "z": 5,
      "name": "Rock_Runic_Cobble_Half",
      "rotation": 1
    },
    {
      "x": -17,
      "y": 0,
      "z": 6,
      "name": "Rock_Runic_Brick",
      "rotation": 1
    },
    {
      "x": -17,
      "y": 1,
      "z": 6,
      "name": "Rock_Runic_Cobble",
      "rotation": 1
    },
    {
      "x": -17,
      "y": 2,
      "z": 6,
      "name": "Rock_Runic_Cobble",
      "rotation": 1
    },
    {
      "x": -17,
      "y": 3,
      "z": 6,
      "name": "Rock_Runic_Cobble",
      "rotation": 1
    },
    {
      "x": -17,
      "y": 4,
      "z": 6,
      "name": "Rock_Runic_Cobble",
      "rotation": 1
    },
    {
      "x": -17,
      "y": 5,
      "z": 6,
      "name": "Rock_Runic_Cobble_Half",
      "rotation": 1
    },
    {
      "x": -17,
      "y": 0,
      "z": 7,
      "name": "Rock_Runic_Brick",
      "rotation": 1
    },
    {
      "x": -17,
      "y": 1,
      "z": 7,
      "name": "Rock_Runic_Cobble",
      "rotation": 1
    },
    {
      "x": -17,
      "y": 2,
      "z": 7,
      "name": "Rock_Runic_Cobble",
      "rotation": 1
    },
    {
      "x": -17,
      "y": 3,
      "z": 7,
      "name": "Rock_Runic_Cobble",
      "rotation": 1
    },
    {
      "x": -17,
      "y": 4,
      "z": 7,
      "name": "Rock_Runic_Cobble",
      "rotation": 1
    },
    {
      "x": -17,
      "y": 5,
      "z": 7,
      "name": "Rock_Runic_Cobble_Half",
      "rotation": 1
    },
    {
      "x": -17,
      "y": 0,
      "z": 8,
      "name": "Rock_Runic_Brick",
      "rotation": 1
    },
    {
      "x": -17,
      "y": 1,
      "z": 8,
      "name": "Rock_Runic_Cobble",
      "rotation": 1
    },
    {
      "x": -17,
      "y": 2,
      "z": 8,
      "name": "Rock_Runic_Cobble",
      "rotation": 1
    },
    {
      "x": -17,
      "y": 3,
      "z": 8,
      "name": "Rock_Runic_Cobble",
      "rotation": 1
    },
    {
      "x": -17,
      "y": 4,
      "z": 8,
      "name": "Rock_Runic_Cobble",
      "rotation": 1
    },
    {
      "x": -17,
      "y": 5,
      "z": 8,
      "name": "Rock_Runic_Cobble_Half",
      "rotation": 1
    },
    {
      "x": -17,
      "y": 0,
      "z": 9,
      "name": "Rock_Runic_Brick",
      "rotation": 1
    },
    {
      "x": -17,
      "y": 1,
      "z": 9,
      "name": "Rock_Runic_Cobble",
      "rotation": 1
    },
    {
      "x": -17,
      "y": 2,
      "z": 9,
      "name": "Rock_Runic_Cobble",
      "rotation": 1
    },
    {
      "x": -17,
      "y": 3,
      "z": 9,
      "name": "Rock_Runic_Cobble",
      "rotation": 1
    },
    {
      "x": -17,
      "y": 4,
      "z": 9,
      "name": "Rock_Runic_Cobble",
      "rotation": 1
    },
    {
      "x": -17,
      "y": 5,
      "z": 9,
      "name": "Rock_Runic_Cobble_Half",
      "rotation": 1
    },
    {
      "x": -17,
      "y": 0,
      "z": 10,
      "name": "Rock_Runic_Brick",
      "rotation": 2
    },
    {
      "x": -17,
      "y": 1,
      "z": 10,
      "name": "Rock_Runic_Cobble",
      "rotation": 2
    },
    {
      "x": -17,
      "y": 2,
      "z": 10,
      "name": "Rock_Runic_Cobble",
      "rotation": 2
    },
    {
      "x": -17,
      "y": 3,
      "z": 10,
      "name": "Rock_Runic_Cobble",
      "rotation": 2
    },
    {
      "x": -17,
      "y": 4,
      "z": 10,
      "name": "Rock_Runic_Cobble",
      "rotation": 2
    },
    {
      "x": -17,
      "y": 5,
      "z": 10,
      "name": "Rock_Runic_Cobble_Half",
      "rotation": 2
    },
    {
      "x": -17,
      "y": 0,
      "z": 11,
      "name": "Rock_Runic_Brick",
      "rotation": 2
    },
    {
      "x": -17,
      "y": 1,
      "z": 11,
      "name": "Rock_Runic_Cobble",
      "rotation": 2
    },
    {
      "x": -17,
      "y": 2,
      "z": 11,
      "name": "Rock_Runic_Cobble",
      "rotation": 2
    },
    {
      "x": -17,
      "y": 3,
      "z": 11,
      "name": "Rock_Runic_Cobble",
      "rotation": 2
    },
    {
      "x": -17,
      "y": 4,
      "z": 11,
      "name": "Rock_Runic_Cobble",
      "rotation": 2
    },
    {
      "x": -17,
      "y": 5,
      "z": 11,
      "name": "Rock_Runic_Cobble_Half",
      "rotation": 2
    },
    {
      "x": -17,
      "y": 0,
      "z": 12,
      "name": "Rock_Runic_Brick",
      "rotation": 2
    },
    {
      "x": -17,
      "y": 1,
      "z": 12,
      "name": "Rock_Runic_Cobble",
      "rotation": 2
    },
    {
      "x": -17,
      "y": 2,
      "z": 12,
      "name": "Rock_Runic_Cobble",
      "rotation": 2
    },
    {
      "x": -17,
      "y": 3,
      "z": 12,
      "name": "Rock_Runic_Cobble",
      "rotation": 2
    },
    {
      "x": -17,
      "y": 4,
      "z": 12,
      "name": "Rock_Runic_Cobble",
      "rotation": 2
    },
    {
      "x": -17,
      "y": 5,
      "z": 12,
      "name": "Rock_Runic_Cobble_Half",
      "rotation": 2
    },
    {
      "x": -17,
      "y": 0,
      "z": 13,
      "name": "Rock_Runic_Brick",
      "rotation": 2
    },
    {
      "x": -17,
      "y": 1,
      "z": 13,
      "name": "Rock_Runic_Cobble",
      "rotation": 2
    },
    {
      "x": -17,
      "y": 2,
      "z": 13,
      "name": "Rock_Runic_Cobble",
      "rotation": 2
    },
    {
      "x": -17,
      "y": 3,
      "z": 13,
      "name": "Rock_Runic_Cobble",
      "rotation": 2
    },
    {
      "x": -17,
      "y": 4,
      "z": 13,
      "name": "Rock_Runic_Cobble",
      "rotation": 2
    },
    {
      "x": -17,
      "y": 5,
      "z": 13,
      "name": "Rock_Runic_Cobble_Half",
      "rotation": 2
    },
    {
      "x": -17,
      "y": 0,
      "z": 14,
      "name": "Rock_Runic_Brick",
      "rotation": 2
    },
    {
      "x": -17,
      "y": 1,
      "z": 14,
      "name": "Rock_Runic_Cobble",
      "rotation": 2
    },
    {
      "x": -17,
      "y": 2,
      "z": 14,
      "name": "Rock_Runic_Cobble",
      "rotation": 2
    },
    {
      "x": -17,
      "y": 3,
      "z": 14,
      "name": "Rock_Runic_Cobble",
      "rotation": 2
    },
    {
      "x": -17,
      "y": 4,
      "z": 14,
      "name": "Rock_Runic_Cobble",
      "rotation": 2
    },
    {
      "x": -17,
      "y": 5,
      "z": 14,
      "name": "Rock_Runic_Cobble_Half",
      "rotation": 2
    },
    {
      "x": -17,
      "y": 0,
      "z": 15,
      "name": "Rock_Runic_Brick",
      "rotation": 2
    },
    {
      "x": -17,
      "y": 1,
      "z": 15,
      "name": "Rock_Runic_Cobble",
      "rotation": 2
    },
    {
      "x": -17,
      "y": 2,
      "z": 15,
      "name": "Rock_Runic_Cobble",
      "rotation": 2
    },
    {
      "x": -17,
      "y": 3,
      "z": 15,
      "name": "Rock_Runic_Cobble",
      "rotation": 2
    },
    {
      "x": -17,
      "y": 4,
      "z": 15,
      "name": "Rock_Runic_Cobble",
      "rotation": 2
    },
    {
      "x": -17,
      "y": 5,
      "z": 15,
      "name": "Rock_Runic_Cobble_Half",
      "rotation": 2
    },
    {
      "x": -17,
      "y": 0,
      "z": 16,
      "name": "Soil_Grass"
    },
    {
      "x": -16,
      "y": 0,
      "z": -15,
      "name": "Soil_Grass"
    },
    {
      "x": -16,
      "y": 0,
      "z": -14,
      "name": "Rock_Runic_Brick",
      "rotation": 1
    },
    {
      "x": -16,
      "y": 1,
      "z": -14,
      "name": "Rock_Runic_Cobble",
      "rotation": 1
    },
    {
      "x": -16,
      "y": 2,
      "z": -14,
      "name": "Rock_Runic_Cobble",
      "rotation": 1
    },
    {
      "x": -16,
      "y": 3,
      "z": -14,
      "name": "Rock_Runic_Cobble",
      "rotation": 1
    },
    {
      "x": -16,
      "y": 4,
      "z": -14,
      "name": "Rock_Runic_Cobble",
      "rotation": 1
    },
    {
      "x": -16,
      "y": 5,
      "z": -14,
      "name": "Rock_Runic_Cobble_Half",
      "rotation": 1
    },
    {
      "x": -16,
      "y": 0,
      "z": -13,
      "name": "Rock_Runic_Brick",
      "rotation": 1
    },
    {
      "x": -16,
      "y": 1,
      "z": -13,
      "name": "Rock_Runic_Cobble",
      "rotation": 1
    },
    {
      "x": -16,
      "y": 2,
      "z": -13,
      "name": "Rock_Runic_Cobble",
      "rotation": 1
    },
    {
      "x": -16,
      "y": 3,
      "z": -13,
      "name": "Rock_Runic_Cobble",
      "rotation": 1
    },
    {
      "x": -16,
      "y": 4,
      "z": -13,
      "name": "Rock_Runic_Cobble",
      "rotation": 1
    },
    {
      "x": -16,
      "y": 5,
      "z": -13,
      "name": "Rock_Runic_Cobble_Half",
      "rotation": 1
    },
    {
      "x": -16,
      "y": 0,
      "z": -12,
      "name": "Rock_Runic_Brick",
      "rotation": 1
    },
    {
      "x": -16,
      "y": 0,
      "z": -11,
      "name": "Rock_Runic_Brick",
      "rotation": 1
    },
    {
      "x": -16,
      "y": 0,
      "z": -10,
      "name": "Rock_Runic_Brick",
      "rotation": 1
    },
    {
      "x": -16,
      "y": 1,
      "z": -10,
      "name": "Rock_Runic_Cobble",
      "rotation": 1
    },
    {
      "x": -16,
      "y": 2,
      "z": -10,
      "name": "Rock_Runic_Cobble",
      "rotation": 1
    },
    {
      "x": -16,
      "y": 3,
      "z": -10,
      "name": "Rock_Runic_Cobble",
      "rotation": 1
    },
    {
      "x": -16,
      "y": 4,
      "z": -10,
      "name": "Rock_Runic_Cobble",
      "rotation": 1
    },
    {
      "x": -16,
      "y": 5,
      "z": -10,
      "name": "Rock_Runic_Cobble_Half",
      "rotation": 1
    },
    {
      "x": -16,
      "y": 0,
      "z": -9,
      "name": "Rock_Runic_Brick",
      "rotation": 1
    },
    {
      "x": -16,
      "y": 1,
      "z": -9,
      "name": "Rock_Runic_Cobble",
      "rotation": 1
    },
    {
      "x": -16,
      "y": 2,
      "z": -9,
      "name": "Rock_Runic_Cobble",
      "rotation": 1
    },
    {
      "x": -16,
      "y": 3,
      "z": -9,
      "name": "Rock_Runic_Cobble",
      "rotation": 1
    },
    {
      "x": -16,
      "y": 4,
      "z": -9,
      "name": "Rock_Runic_Cobble",
      "rotation": 1
    },
    {
      "x": -16,
      "y": 5,
      "z": -9,
      "name": "Rock_Runic_Cobble_Half",
      "rotation": 1
    },
    {
      "x": -16,
      "y": 0,
      "z": -8,
      "name": "Rock_Runic_Brick",
      "rotation": 2
    },
    {
      "x": -16,
      "y": 1,
      "z": -8,
      "name": "Rock_Runic_Cobble",
      "rotation": 2
    },
    {
      "x": -16,
      "y": 2,
      "z": -8,
      "name": "Rock_Runic_Cobble",
      "rotation": 2
    },
    {
      "x": -16,
      "y": 3,
      "z": -8,
      "name": "Rock_Runic_Cobble",
      "rotation": 2
    },
    {
      "x": -16,
      "y": 4,
      "z": -8,
      "name": "Rock_Runic_Cobble",
      "rotation": 2
    },
    {
      "x": -16,
      "y": 5,
      "z": -8,
      "name": "Rock_Runic_Cobble_Half",
      "rotation": 2
    },
    {
      "x": -16,
      "y": 0,
      "z": -7,
      "name": "Rock_Runic_Brick",
      "rotation": 2
    },
    {
      "x": -16,
      "y": 1,
      "z": -7,
      "name": "Rock_Runic_Cobble",
      "rotation": 2
    },
    {
      "x": -16,
      "y": 2,
      "z": -7,
      "name": "Rock_Runic_Cobble",
      "rotation": 2
    },
    {
      "x": -16,
      "y": 3,
      "z": -7,
      "name": "Rock_Runic_Cobble",
      "rotation": 2
    },
    {
      "x": -16,
      "y": 4,
      "z": -7,
      "name": "Rock_Runic_Cobble",
      "rotation": 2
    },
    {
      "x": -16,
      "y": 5,
      "z": -7,
      "name": "Rock_Runic_Cobble_Half",
      "rotation": 2
    },
    {
      "x": -16,
      "y": 0,
      "z": -6,
      "name": "Rock_Runic_Brick",
      "rotation": 2
    },
    {
      "x": -16,
      "y": 1,
      "z": -6,
      "name": "Rock_Runic_Cobble",
      "rotation": 2
    },
    {
      "x": -16,
      "y": 2,
      "z": -6,
      "name": "Rock_Runic_Cobble",
      "rotation": 2
    },
    {
      "x": -16,
      "y": 3,
      "z": -6,
      "name": "Rock_Runic_Cobble",
      "rotation": 2
    },
    {
      "x": -16,
      "y": 4,
      "z": -6,
      "name": "Rock_Runic_Cobble",
      "rotation": 2
    },
    {
      "x": -16,
      "y": 5,
      "z": -6,
      "name": "Rock_Runic_Cobble_Half",
      "rotation": 2
    },
    {
      "x": -16,
      "y": 0,
      "z": -5,
      "name": "Rock_Runic_Brick",
      "rotation": 2
    },
    {
      "x": -16,
      "y": 1,
      "z": -5,
      "name": "Rock_Runic_Cobble",
      "rotation": 2
    },
    {
      "x": -16,
      "y": 2,
      "z": -5,
      "name": "Rock_Runic_Cobble",
      "rotation": 2
    },
    {
      "x": -16,
      "y": 3,
      "z": -5,
      "name": "Rock_Runic_Cobble",
      "rotation": 2
    },
    {
      "x": -16,
      "y": 4,
      "z": -5,
      "name": "Rock_Runic_Cobble",
      "rotation": 2
    },
    {
      "x": -16,
      "y": 5,
      "z": -5,
      "name": "Rock_Runic_Cobble_Half",
      "rotation": 2
    },
    {
      "x": -16,
      "y": 0,
      "z": -4,
      "name": "Rock_Runic_Brick",
      "rotation": 2
    },
    {
      "x": -16,
      "y": 1,
      "z": -4,
      "name": "Rock_Runic_Cobble",
      "rotation": 2
    },
    {
      "x": -16,
      "y": 2,
      "z": -4,
      "name": "Rock_Runic_Cobble",
      "rotation": 2
    },
    {
      "x": -16,
      "y": 3,
      "z": -4,
      "name": "Rock_Runic_Cobble",
      "rotation": 2
    },
    {
      "x": -16,
      "y": 4,
      "z": -4,
      "name": "Rock_Runic_Cobble",
      "rotation": 2
    },
    {
      "x": -16,
      "y": 5,
      "z": -4,
      "name": "Rock_Runic_Cobble_Half",
      "rotation": 2
    },
    {
      "x": -16,
      "y": 0,
      "z": -3,
      "name": "Rock_Runic_Brick",
      "rotation": 2
    },
    {
      "x": -16,
      "y": 1,
      "z": -3,
      "name": "Rock_Runic_Cobble",
      "rotation": 2
    },
    {
      "x": -16,
      "y": 2,
      "z": -3,
      "name": "Rock_Runic_Cobble",
      "rotation": 2
    },
    {
      "x": -16,
      "y": 3,
      "z": -3,
      "name": "Rock_Runic_Cobble",
      "rotation": 2
    },
    {
      "x": -16,
      "y": 4,
      "z": -3,
      "name": "Rock_Runic_Cobble",
      "rotation": 2
    },
    {
      "x": -16,
      "y": 5,
      "z": -3,
      "name": "Rock_Runic_Cobble_Half",
      "rotation": 2
    },
    {
      "x": -16,
      "y": 0,
      "z": -2,
      "name": "Rock_Runic_Brick"
    },
    {
      "x": -16,
      "y": 1,
      "z": -2,
      "name": "Rock_Runic_Cobble"
    },
    {
      "x": -16,
      "y": 2,
      "z": -2,
      "name": "Rock_Runic_Cobble"
    },
    {
      "x": -16,
      "y": 3,
      "z": -2,
      "name": "Rock_Runic_Cobble"
    },
    {
      "x": -16,
      "y": 4,
      "z": -2,
      "name": "Rock_Runic_Cobble"
    },
    {
      "x": -16,
      "y": 5,
      "z": -2,
      "name": "Rock_Runic_Cobble_Half"
    },
    {
      "x": -16,
      "y": 0,
      "z": -1,
      "name": "Rock_Runic_Brick"
    },
    {
      "x": -16,
      "y": 1,
      "z": -1,
      "name": "Rock_Runic_Cobble"
    },
    {
      "x": -16,
      "y": 2,
      "z": -1,
      "name": "Rock_Runic_Cobble"
    },
    {
      "x": -16,
      "y": 3,
      "z": -1,
      "name": "Rock_Runic_Cobble"
    },
    {
      "x": -16,
      "y": 4,
      "z": -1,
      "name": "Rock_Runic_Cobble"
    },
    {
      "x": -16,
      "y": 5,
      "z": -1,
      "name": "Rock_Runic_Cobble_Half"
    },
    {
      "x": -16,
      "y": 0,
      "z": 0,
      "name": "Rock_Runic_Brick"
    },
    {
      "x": -16,
      "y": 0,
      "z": 1,
      "name": "Rock_Runic_Brick"
    },
    {
      "x": -16,
      "y": 0,
      "z": 2,
      "name": "Rock_Runic_Brick"
    },
    {
      "x": -16,
      "y": 1,
      "z": 2,
      "name": "Rock_Runic_Cobble"
    },
    {
      "x": -16,
      "y": 2,
      "z": 2,
      "name": "Rock_Runic_Cobble"
    },
    {
      "x": -16,
      "y": 3,
      "z": 2,
      "name": "Rock_Runic_Cobble"
    },
    {
      "x": -16,
      "y": 4,
      "z": 2,
      "name": "Rock_Runic_Cobble"
    },
    {
      "x": -16,
      "y": 5,
      "z": 2,
      "name": "Rock_Runic_Cobble_Half"
    },
    {
      "x": -16,
      "y": 0,
      "z": 3,
      "name": "Rock_Runic_Brick"
    },
    {
      "x": -16,
      "y": 1,
      "z": 3,
      "name": "Rock_Runic_Cobble"
    },
    {
      "x": -16,
      "y": 2,
      "z": 3,
      "name": "Rock_Runic_Cobble"
    },
    {
      "x": -16,
      "y": 3,
      "z": 3,
      "name": "Rock_Runic_Cobble"
    },
    {
      "x": -16,
      "y": 4,
      "z": 3,
      "name": "Rock_Runic_Cobble"
    },
    {
      "x": -16,
      "y": 5,
      "z": 3,
      "name": "Rock_Runic_Cobble_Half"
    },
    {
      "x": -16,
      "y": 0,
      "z": 4,
      "name": "Rock_Runic_Brick",
      "rotation": 1
    },
    {
      "x": -16,
      "y": 1,
      "z": 4,
      "name": "Rock_Runic_Cobble",
      "rotation": 1
    },
    {
      "x": -16,
      "y": 2,
      "z": 4,
      "name": "Rock_Runic_Cobble",
      "rotation": 1
    },
    {
      "x": -16,
      "y": 3,
      "z": 4,
      "name": "Rock_Runic_Cobble",
      "rotation": 1
    },
    {
      "x": -16,
      "y": 4,
      "z": 4,
      "name": "Rock_Runic_Cobble",
      "rotation": 1
    },
    {
      "x": -16,
      "y": 5,
      "z": 4,
      "name": "Rock_Runic_Cobble_Half",
      "rotation": 1
    },
    {
      "x": -16,
      "y": 0,
      "z": 5,
      "name": "Rock_Runic_Brick",
      "rotation": 1
    },
    {
      "x": -16,
      "y": 1,
      "z": 5,
      "name": "Rock_Runic_Cobble",
      "rotation": 1
    },
    {
      "x": -16,
      "y": 2,
      "z": 5,
      "name": "Rock_Runic_Cobble",
      "rotation": 1
    },
    {
      "x": -16,
      "y": 3,
      "z": 5,
      "name": "Rock_Runic_Cobble",
      "rotation": 1
    },
    {
      "x": -16,
      "y": 4,
      "z": 5,
      "name": "Rock_Runic_Cobble",
      "rotation": 1
    },
    {
      "x": -16,
      "y": 5,
      "z": 5,
      "name": "Rock_Runic_Cobble_Half",
      "rotation": 1
    },
    {
      "x": -16,
      "y": 0,
      "z": 6,
      "name": "Rock_Runic_Brick",
      "rotation": 1
    },
    {
      "x": -16,
      "y": 1,
      "z": 6,
      "name": "Rock_Runic_Cobble",
      "rotation": 1
    },
    {
      "x": -16,
      "y": 2,
      "z": 6,
      "name": "Rock_Runic_Cobble",
      "rotation": 1
    },
    {
      "x": -16,
      "y": 3,
      "z": 6,
      "name": "Rock_Runic_Cobble",
      "rotation": 1
    },
    {
      "x": -16,
      "y": 4,
      "z": 6,
      "name": "Rock_Runic_Cobble",
      "rotation": 1
    },
    {
      "x": -16,
      "y": 5,
      "z": 6,
      "name": "Rock_Runic_Cobble_Half",
      "rotation": 1
    },
    {
      "x": -16,
      "y": 0,
      "z": 7,
      "name": "Rock_Runic_Brick",
      "rotation": 1
    },
    {
      "x": -16,
      "y": 1,
      "z": 7,
      "name": "Rock_Runic_Cobble",
      "rotation": 1
    },
    {
      "x": -16,
      "y": 2,
      "z": 7,
      "name": "Rock_Runic_Cobble",
      "rotation": 1
    },
    {
      "x": -16,
      "y": 3,
      "z": 7,
      "name": "Rock_Runic_Cobble",
      "rotation": 1
    },
    {
      "x": -16,
      "y": 4,
      "z": 7,
      "name": "Rock_Runic_Cobble",
      "rotation": 1
    },
    {
      "x": -16,
      "y": 5,
      "z": 7,
      "name": "Rock_Runic_Cobble_Half",
      "rotation": 1
    },
    {
      "x": -16,
      "y": 0,
      "z": 8,
      "name": "Rock_Runic_Brick",
      "rotation": 1
    },
    {
      "x": -16,
      "y": 1,
      "z": 8,
      "name": "Rock_Runic_Cobble",
      "rotation": 1
    },
    {
      "x": -16,
      "y": 2,
      "z": 8,
      "name": "Rock_Runic_Cobble",
      "rotation": 1
    },
    {
      "x": -16,
      "y": 3,
      "z": 8,
      "name": "Rock_Runic_Cobble",
      "rotation": 1
    },
    {
      "x": -16,
      "y": 4,
      "z": 8,
      "name": "Rock_Runic_Cobble",
      "rotation": 1
    },
    {
      "x": -16,
      "y": 5,
      "z": 8,
      "name": "Rock_Runic_Cobble_Half",
      "rotation": 1
    },
    {
      "x": -16,
      "y": 0,
      "z": 9,
      "name": "Rock_Runic_Brick",
      "rotation": 1
    },
    {
      "x": -16,
      "y": 1,
      "z": 9,
      "name": "Rock_Runic_Cobble",
      "rotation": 1
    },
    {
      "x": -16,
      "y": 2,
      "z": 9,
      "name": "Rock_Runic_Cobble",
      "rotation": 1
    },
    {
      "x": -16,
      "y": 3,
      "z": 9,
      "name": "Rock_Runic_Cobble",
      "rotation": 1
    },
    {
      "x": -16,
      "y": 4,
      "z": 9,
      "name": "Rock_Runic_Cobble",
      "rotation": 1
    },
    {
      "x": -16,
      "y": 5,
      "z": 9,
      "name": "Rock_Runic_Cobble_Half",
      "rotation": 1
    },
    {
      "x": -16,
      "y": 0,
      "z": 10,
      "name": "Rock_Runic_Brick",
      "rotation": 2
    },
    {
      "x": -16,
      "y": 1,
      "z": 10,
      "name": "Rock_Runic_Cobble",
      "rotation": 2
    },
    {
      "x": -16,
      "y": 2,
      "z": 10,
      "name": "Rock_Runic_Cobble",
      "rotation": 2
    },
    {
      "x": -16,
      "y": 3,
      "z": 10,
      "name": "Rock_Runic_Cobble",
      "rotation": 2
    },
    {
      "x": -16,
      "y": 4,
      "z": 10,
      "name": "Rock_Runic_Cobble",
      "rotation": 2
    },
    {
      "x": -16,
      "y": 5,
      "z": 10,
      "name": "Rock_Runic_Cobble_Half",
      "rotation": 2
    },
    {
      "x": -16,
      "y": 0,
      "z": 11,
      "name": "Rock_Runic_Brick",
      "rotation": 2
    },
    {
      "x": -16,
      "y": 1,
      "z": 11,
      "name": "Rock_Runic_Cobble",
      "rotation": 2
    },
    {
      "x": -16,
      "y": 2,
      "z": 11,
      "name": "Rock_Runic_Cobble",
      "rotation": 2
    },
    {
      "x": -16,
      "y": 3,
      "z": 11,
      "name": "Rock_Runic_Cobble",
      "rotation": 2
    },
    {
      "x": -16,
      "y": 4,
      "z": 11,
      "name": "Rock_Runic_Cobble",
      "rotation": 2
    },
    {
      "x": -16,
      "y": 5,
      "z": 11,
      "name": "Rock_Runic_Cobble_Half",
      "rotation": 2
    },
    {
      "x": -16,
      "y": 0,
      "z": 12,
      "name": "Rock_Runic_Brick",
      "rotation": 2
    },
    {
      "x": -16,
      "y": 1,
      "z": 12,
      "name": "Rock_Runic_Cobble",
      "rotation": 2
    },
    {
      "x": -16,
      "y": 2,
      "z": 12,
      "name": "Rock_Runic_Cobble",
      "rotation": 2
    },
    {
      "x": -16,
      "y": 3,
      "z": 12,
      "name": "Rock_Runic_Cobble",
      "rotation": 2
    },
    {
      "x": -16,
      "y": 4,
      "z": 12,
      "name": "Rock_Runic_Cobble",
      "rotation": 2
    },
    {
      "x": -16,
      "y": 5,
      "z": 12,
      "name": "Rock_Runic_Cobble_Half",
      "rotation": 2
    },
    {
      "x": -16,
      "y": 0,
      "z": 13,
      "name": "Rock_Runic_Brick",
      "rotation": 2
    },
    {
      "x": -16,
      "y": 1,
      "z": 13,
      "name": "Rock_Runic_Cobble",
      "rotation": 2
    },
    {
      "x": -16,
      "y": 2,
      "z": 13,
      "name": "Rock_Runic_Cobble",
      "rotation": 2
    },
    {
      "x": -16,
      "y": 3,
      "z": 13,
      "name": "Rock_Runic_Cobble",
      "rotation": 2
    },
    {
      "x": -16,
      "y": 4,
      "z": 13,
      "name": "Rock_Runic_Cobble",
      "rotation": 2
    },
    {
      "x": -16,
      "y": 5,
      "z": 13,
      "name": "Rock_Runic_Cobble_Half",
      "rotation": 2
    },
    {
      "x": -16,
      "y": 0,
      "z": 14,
      "name": "Rock_Runic_Brick",
      "rotation": 2
    },
    {
      "x": -16,
      "y": 1,
      "z": 14,
      "name": "Rock_Runic_Cobble",
      "rotation": 2
    },
    {
      "x": -16,
      "y": 2,
      "z": 14,
      "name": "Rock_Runic_Cobble",
      "rotation": 2
    },
    {
      "x": -16,
      "y": 3,
      "z": 14,
      "name": "Rock_Runic_Cobble",
      "rotation": 2
    },
    {
      "x": -16,
      "y": 4,
      "z": 14,
      "name": "Rock_Runic_Cobble",
      "rotation": 2
    },
    {
      "x": -16,
      "y": 5,
      "z": 14,
      "name": "Rock_Runic_Cobble_Half",
      "rotation": 2
    },
    {
      "x": -16,
      "y": 0,
      "z": 15,
      "name": "Rock_Runic_Brick",
      "rotation": 2
    },
    {
      "x": -16,
      "y": 1,
      "z": 15,
      "name": "Rock_Runic_Cobble",
      "rotation": 2
    },
    {
      "x": -16,
      "y": 2,
      "z": 15,
      "name": "Rock_Runic_Cobble",
      "rotation": 2
    },
    {
      "x": -16,
      "y": 3,
      "z": 15,
      "name": "Rock_Runic_Cobble",
      "rotation": 2
    },
    {
      "x": -16,
      "y": 4,
      "z": 15,
      "name": "Rock_Runic_Cobble",
      "rotation": 2
    },
    {
      "x": -16,
      "y": 5,
      "z": 15,
      "name": "Rock_Runic_Cobble_Half",
      "rotation": 2
    },
    {
      "x": -16,
      "y": 0,
      "z": 16,
      "name": "Soil_Grass"
    },
    {
      "x": -15,
      "y": 0,
      "z": -15,
      "name": "Soil_Grass"
    },
    {
      "x": -15,
      "y": 0,
      "z": -14,
      "name": "Rock_Runic_Brick",
      "rotation": 1
    },
    {
      "x": -15,
      "y": 1,
      "z": -14,
      "name": "Rock_Runic_Cobble",
      "rotation": 1
    },
    {
      "x": -15,
      "y": 2,
      "z": -14,
      "name": "Rock_Runic_Cobble",
      "rotation": 1
    },
    {
      "x": -15,
      "y": 3,
      "z": -14,
      "name": "Rock_Runic_Cobble",
      "rotation": 1
    },
    {
      "x": -15,
      "y": 4,
      "z": -14,
      "name": "Rock_Runic_Cobble",
      "rotation": 1
    },
    {
      "x": -15,
      "y": 5,
      "z": -14,
      "name": "Rock_Runic_Cobble_Half",
      "rotation": 1
    },
    {
      "x": -15,
      "y": 0,
      "z": -13,
      "name": "Rock_Runic_Brick",
      "rotation": 1
    },
    {
      "x": -15,
      "y": 1,
      "z": -13,
      "name": "Rock_Runic_Cobble",
      "rotation": 1
    },
    {
      "x": -15,
      "y": 2,
      "z": -13,
      "name": "Rock_Runic_Cobble",
      "rotation": 1
    },
    {
      "x": -15,
      "y": 3,
      "z": -13,
      "name": "Rock_Runic_Cobble",
      "rotation": 1
    },
    {
      "x": -15,
      "y": 4,
      "z": -13,
      "name": "Rock_Runic_Cobble",
      "rotation": 1
    },
    {
      "x": -15,
      "y": 5,
      "z": -13,
      "name": "Rock_Runic_Cobble_Half",
      "rotation": 1
    },
    {
      "x": -15,
      "y": 0,
      "z": -12,
      "name": "Rock_Runic_Brick",
      "rotation": 1
    },
    {
      "x": -15,
      "y": 0,
      "z": -11,
      "name": "Rock_Runic_Brick",
      "rotation": 1
    },
    {
      "x": -15,
      "y": 0,
      "z": -10,
      "name": "Rock_Runic_Brick",
      "rotation": 1
    },
    {
      "x": -15,
      "y": 0,
      "z": -9,
      "name": "Rock_Runic_Brick",
      "rotation": 1
    },
    {
      "x": -15,
      "y": 0,
      "z": -8,
      "name": "Rock_Runic_Brick",
      "rotation": 2
    },
    {
      "x": -15,
      "y": 0,
      "z": -7,
      "name": "Rock_Runic_Brick",
      "rotation": 2
    },
    {
      "x": -15,
      "y": 0,
      "z": -6,
      "name": "Rock_Runic_Brick",
      "rotation": 2
    },
    {
      "x": -15,
      "y": 0,
      "z": -5,
      "name": "Rock_Runic_Brick",
      "rotation": 2
    },
    {
      "x": -15,
      "y": 0,
      "z": -4,
      "name": "Rock_Runic_Brick",
      "rotation": 2
    },
    {
      "x": -15,
      "y": 1,
      "z": -4,
      "name": "Rock_Runic_Cobble",
      "rotation": 2
    },
    {
      "x": -15,
      "y": 2,
      "z": -4,
      "name": "Rock_Runic_Cobble",
      "rotation": 2
    },
    {
      "x": -15,
      "y": 3,
      "z": -4,
      "name": "Rock_Runic_Cobble",
      "rotation": 2
    },
    {
      "x": -15,
      "y": 4,
      "z": -4,
      "name": "Rock_Runic_Cobble",
      "rotation": 2
    },
    {
      "x": -15,
      "y": 5,
      "z": -4,
      "name": "Rock_Runic_Cobble_Half",
      "rotation": 2
    },
    {
      "x": -15,
      "y": 0,
      "z": -3,
      "name": "Rock_Runic_Brick",
      "rotation": 2
    },
    {
      "x": -15,
      "y": 1,
      "z": -3,
      "name": "Rock_Runic_Cobble",
      "rotation": 2
    },
    {
      "x": -15,
      "y": 2,
      "z": -3,
      "name": "Rock_Runic_Cobble",
      "rotation": 2
    },
    {
      "x": -15,
      "y": 3,
      "z": -3,
      "name": "Rock_Runic_Cobble",
      "rotation": 2
    },
    {
      "x": -15,
      "y": 4,
      "z": -3,
      "name": "Rock_Runic_Cobble",
      "rotation": 2
    },
    {
      "x": -15,
      "y": 5,
      "z": -3,
      "name": "Rock_Runic_Cobble_Half",
      "rotation": 2
    },
    {
      "x": -15,
      "y": 0,
      "z": -2,
      "name": "Rock_Runic_Brick"
    },
    {
      "x": -15,
      "y": 1,
      "z": -2,
      "name": "Rock_Runic_Cobble"
    },
    {
      "x": -15,
      "y": 2,
      "z": -2,
      "name": "Rock_Runic_Cobble"
    },
    {
      "x": -15,
      "y": 3,
      "z": -2,
      "name": "Rock_Runic_Cobble"
    },
    {
      "x": -15,
      "y": 4,
      "z": -2,
      "name": "Rock_Runic_Cobble"
    },
    {
      "x": -15,
      "y": 5,
      "z": -2,
      "name": "Rock_Runic_Cobble_Half"
    },
    {
      "x": -15,
      "y": 0,
      "z": -1,
      "name": "Rock_Runic_Brick"
    },
    {
      "x": -15,
      "y": 1,
      "z": -1,
      "name": "Rock_Runic_Cobble"
    },
    {
      "x": -15,
      "y": 2,
      "z": -1,
      "name": "Rock_Runic_Cobble"
    },
    {
      "x": -15,
      "y": 3,
      "z": -1,
      "name": "Rock_Runic_Cobble"
    },
    {
      "x": -15,
      "y": 4,
      "z": -1,
      "name": "Rock_Runic_Cobble"
    },
    {
      "x": -15,
      "y": 5,
      "z": -1,
      "name": "Rock_Runic_Cobble_Half"
    },
    {
      "x": -15,
      "y": 0,
      "z": 0,
      "name": "Rock_Runic_Brick"
    },
    {
      "x": -15,
      "y": 0,
      "z": 1,
      "name": "Rock_Runic_Brick"
    },
    {
      "x": -15,
      "y": 0,
      "z": 2,
      "name": "Rock_Runic_Brick"
    },
    {
      "x": -15,
      "y": 1,
      "z": 2,
      "name": "Rock_Runic_Cobble"
    },
    {
      "x": -15,
      "y": 2,
      "z": 2,
      "name": "Rock_Runic_Cobble"
    },
    {
      "x": -15,
      "y": 3,
      "z": 2,
      "name": "Rock_Runic_Cobble"
    },
    {
      "x": -15,
      "y": 4,
      "z": 2,
      "name": "Rock_Runic_Cobble"
    },
    {
      "x": -15,
      "y": 5,
      "z": 2,
      "name": "Rock_Runic_Cobble_Half"
    },
    {
      "x": -15,
      "y": 0,
      "z": 3,
      "name": "Rock_Runic_Brick"
    },
    {
      "x": -15,
      "y": 1,
      "z": 3,
      "name": "Rock_Runic_Cobble"
    },
    {
      "x": -15,
      "y": 2,
      "z": 3,
      "name": "Rock_Runic_Cobble"
    },
    {
      "x": -15,
      "y": 3,
      "z": 3,
      "name": "Rock_Runic_Cobble"
    },
    {
      "x": -15,
      "y": 4,
      "z": 3,
      "name": "Rock_Runic_Cobble"
    },
    {
      "x": -15,
      "y": 5,
      "z": 3,
      "name": "Rock_Runic_Cobble_Half"
    },
    {
      "x": -15,
      "y": 0,
      "z": 4,
      "name": "Rock_Runic_Brick",
      "rotation": 1
    },
    {
      "x": -15,
      "y": 1,
      "z": 4,
      "name": "Rock_Runic_Cobble",
      "rotation": 1
    },
    {
      "x": -15,
      "y": 2,
      "z": 4,
      "name": "Rock_Runic_Cobble",
      "rotation": 1
    },
    {
      "x": -15,
      "y": 3,
      "z": 4,
      "name": "Rock_Runic_Cobble",
      "rotation": 1
    },
    {
      "x": -15,
      "y": 4,
      "z": 4,
      "name": "Rock_Runic_Cobble",
      "rotation": 1
    },
    {
      "x": -15,
      "y": 5,
      "z": 4,
      "name": "Rock_Runic_Cobble_Half",
      "rotation": 1
    },
    {
      "x": -15,
      "y": 0,
      "z": 5,
      "name": "Rock_Runic_Brick",
      "rotation": 1
    },
    {
      "x": -15,
      "y": 1,
      "z": 5,
      "name": "Rock_Runic_Cobble",
      "rotation": 1
    },
    {
      "x": -15,
      "y": 2,
      "z": 5,
      "name": "Rock_Runic_Cobble",
      "rotation": 1
    },
    {
      "x": -15,
      "y": 3,
      "z": 5,
      "name": "Rock_Runic_Cobble",
      "rotation": 1
    },
    {
      "x": -15,
      "y": 4,
      "z": 5,
      "name": "Rock_Runic_Cobble",
      "rotation": 1
    },
    {
      "x": -15,
      "y": 5,
      "z": 5,
      "name": "Rock_Runic_Cobble_Half",
      "rotation": 1
    },
    {
      "x": -15,
      "y": 0,
      "z": 6,
      "name": "Rock_Runic_Brick",
      "rotation": 1
    },
    {
      "x": -15,
      "y": 0,
      "z": 7,
      "name": "Rock_Runic_Brick",
      "rotation": 1
    },
    {
      "x": -15,
      "y": 0,
      "z": 8,
      "name": "Rock_Runic_Brick",
      "rotation": 1
    },
    {
      "x": -15,
      "y": 0,
      "z": 9,
      "name": "Rock_Runic_Brick",
      "rotation": 1
    },
    {
      "x": -15,
      "y": 0,
      "z": 10,
      "name": "Rock_Runic_Brick",
      "rotation": 2
    },
    {
      "x": -15,
      "y": 0,
      "z": 11,
      "name": "Rock_Runic_Brick",
      "rotation": 2
    },
    {
      "x": -15,
      "y": 0,
      "z": 12,
      "name": "Rock_Runic_Brick",
      "rotation": 2
    },
    {
      "x": -15,
      "y": 0,
      "z": 13,
      "name": "Rock_Runic_Brick",
      "rotation": 2
    },
    {
      "x": -15,
      "y": 0,
      "z": 14,
      "name": "Rock_Runic_Brick",
      "rotation": 2
    },
    {
      "x": -15,
      "y": 1,
      "z": 14,
      "name": "Rock_Runic_Cobble",
      "rotation": 2
    },
    {
      "x": -15,
      "y": 2,
      "z": 14,
      "name": "Rock_Runic_Cobble",
      "rotation": 2
    },
    {
      "x": -15,
      "y": 3,
      "z": 14,
      "name": "Rock_Runic_Cobble",
      "rotation": 2
    },
    {
      "x": -15,
      "y": 4,
      "z": 14,
      "name": "Rock_Runic_Cobble",
      "rotation": 2
    },
    {
      "x": -15,
      "y": 5,
      "z": 14,
      "name": "Rock_Runic_Cobble_Half",
      "rotation": 2
    },
    {
      "x": -15,
      "y": 0,
      "z": 15,
      "name": "Rock_Runic_Brick",
      "rotation": 2
    },
    {
      "x": -15,
      "y": 1,
      "z": 15,
      "name": "Rock_Runic_Cobble",
      "rotation": 2
    },
    {
      "x": -15,
      "y": 2,
      "z": 15,
      "name": "Rock_Runic_Cobble",
      "rotation": 2
    },
    {
      "x": -15,
      "y": 3,
      "z": 15,
      "name": "Rock_Runic_Cobble",
      "rotation": 2
    },
    {
      "x": -15,
      "y": 4,
      "z": 15,
      "name": "Rock_Runic_Cobble",
      "rotation": 2
    },
    {
      "x": -15,
      "y": 5,
      "z": 15,
      "name": "Rock_Runic_Cobble_Half",
      "rotation": 2
    },
    {
      "x": -15,
      "y": 0,
      "z": 16,
      "name": "Soil_Grass"
    },
    {
      "x": -14,
      "y": 0,
      "z": -15,
      "name": "Soil_Grass"
    },
    {
      "x": -14,
      "y": 0,
      "z": -14,
      "name": "Rock_Runic_Brick",
      "rotation": 1
    },
    {
      "x": -14,
      "y": 1,
      "z": -14,
      "name": "Rock_Runic_Cobble",
      "rotation": 1
    },
    {
      "x": -14,
      "y": 2,
      "z": -14,
      "name": "Rock_Runic_Cobble",
      "rotation": 1
    },
    {
      "x": -14,
      "y": 3,
      "z": -14,
      "name": "Rock_Runic_Cobble",
      "rotation": 1
    },
    {
      "x": -14,
      "y": 4,
      "z": -14,
      "name": "Rock_Runic_Cobble",
      "rotation": 1
    },
    {
      "x": -14,
      "y": 5,
      "z": -14,
      "name": "Rock_Runic_Cobble_Half",
      "rotation": 1
    },
    {
      "x": -14,
      "y": 0,
      "z": -13,
      "name": "Rock_Runic_Brick",
      "rotation": 1
    },
    {
      "x": -14,
      "y": 1,
      "z": -13,
      "name": "Rock_Runic_Cobble",
      "rotation": 1
    },
    {
      "x": -14,
      "y": 2,
      "z": -13,
      "name": "Rock_Runic_Cobble",
      "rotation": 1
    },
    {
      "x": -14,
      "y": 3,
      "z": -13,
      "name": "Rock_Runic_Cobble",
      "rotation": 1
    },
    {
      "x": -14,
      "y": 4,
      "z": -13,
      "name": "Rock_Runic_Cobble",
      "rotation": 1
    },
    {
      "x": -14,
      "y": 5,
      "z": -13,
      "name": "Rock_Runic_Cobble_Half",
      "rotation": 1
    },
    {
      "x": -14,
      "y": 0,
      "z": -12,
      "name": "Rock_Runic_Brick",
      "rotation": 1
    },
    {
      "x": -14,
      "y": 0,
      "z": -11,
      "name": "Rock_Runic_Brick",
      "rotation": 1
    },
    {
      "x": -14,
      "y": 0,
      "z": -10,
      "name": "Rock_Runic_Brick",
      "rotation": 1
    },
    {
      "x": -14,
      "y": 0,
      "z": -9,
      "name": "Rock_Runic_Brick",
      "rotation": 1
    },
    {
      "x": -14,
      "y": 0,
      "z": -8,
      "name": "Rock_Runic_Brick",
      "rotation": 2
    },
    {
      "x": -14,
      "y": 0,
      "z": -7,
      "name": "Rock_Runic_Brick",
      "rotation": 2
    },
    {
      "x": -14,
      "y": 0,
      "z": -6,
      "name": "Rock_Runic_Brick",
      "rotation": 2
    },
    {
      "x": -14,
      "y": 0,
      "z": -5,
      "name": "Rock_Runic_Brick",
      "rotation": 2
    },
    {
      "x": -14,
      "y": 0,
      "z": -4,
      "name": "Rock_Runic_Brick",
      "rotation": 2
    },
    {
      "x": -14,
      "y": 1,
      "z": -4,
      "name": "Rock_Runic_Cobble",
      "rotation": 2
    },
    {
      "x": -14,
      "y": 2,
      "z": -4,
      "name": "Rock_Runic_Cobble",
      "rotation": 2
    },
    {
      "x": -14,
      "y": 3,
      "z": -4,
      "name": "Rock_Runic_Cobble",
      "rotation": 2
    },
    {
      "x": -14,
      "y": 4,
      "z": -4,
      "name": "Rock_Runic_Cobble",
      "rotation": 2
    },
    {
      "x": -14,
      "y": 5,
      "z": -4,
      "name": "Rock_Runic_Cobble_Half",
      "rotation": 2
    },
    {
      "x": -14,
      "y": 0,
      "z": -3,
      "name": "Rock_Runic_Brick",
      "rotation": 2
    },
    {
      "x": -14,
      "y": 1,
      "z": -3,
      "name": "Rock_Runic_Cobble",
      "rotation": 2
    },
    {
      "x": -14,
      "y": 2,
      "z": -3,
      "name": "Rock_Runic_Cobble",
      "rotation": 2
    },
    {
      "x": -14,
      "y": 3,
      "z": -3,
      "name": "Rock_Runic_Cobble",
      "rotation": 2
    },
    {
      "x": -14,
      "y": 4,
      "z": -3,
      "name": "Rock_Runic_Cobble",
      "rotation": 2
    },
    {
      "x": -14,
      "y": 5,
      "z": -3,
      "name": "Rock_Runic_Cobble_Half",
      "rotation": 2
    },
    {
      "x": -14,
      "y": 0,
      "z": -2,
      "name": "Rock_Runic_Brick"
    },
    {
      "x": -14,
      "y": 1,
      "z": -2,
      "name": "Rock_Runic_Cobble"
    },
    {
      "x": -14,
      "y": 2,
      "z": -2,
      "name": "Rock_Runic_Cobble"
    },
    {
      "x": -14,
      "y": 3,
      "z": -2,
      "name": "Rock_Runic_Cobble"
    },
    {
      "x": -14,
      "y": 4,
      "z": -2,
      "name": "Rock_Runic_Cobble"
    },
    {
      "x": -14,
      "y": 5,
      "z": -2,
      "name": "Rock_Runic_Cobble_Half"
    },
    {
      "x": -14,
      "y": 0,
      "z": -1,
      "name": "Rock_Runic_Brick"
    },
    {
      "x": -14,
      "y": 1,
      "z": -1,
      "name": "Rock_Runic_Cobble"
    },
    {
      "x": -14,
      "y": 2,
      "z": -1,
      "name": "Rock_Runic_Cobble"
    },
    {
      "x": -14,
      "y": 3,
      "z": -1,
      "name": "Rock_Runic_Cobble"
    },
    {
      "x": -14,
      "y": 4,
      "z": -1,
      "name": "Rock_Runic_Cobble"
    },
    {
      "x": -14,
      "y": 5,
      "z": -1,
      "name": "Rock_Runic_Cobble_Half"
    },
    {
      "x": -14,
      "y": 0,
      "z": 0,
      "name": "Rock_Runic_Brick"
    },
    {
      "x": -14,
      "y": 0,
      "z": 1,
      "name": "Rock_Runic_Brick"
    },
    {
      "x": -14,
      "y": 0,
      "z": 2,
      "name": "Rock_Runic_Brick"
    },
    {
      "x": -14,
      "y": 1,
      "z": 2,
      "name": "Rock_Runic_Cobble"
    },
    {
      "x": -14,
      "y": 2,
      "z": 2,
      "name": "Rock_Runic_Cobble"
    },
    {
      "x": -14,
      "y": 3,
      "z": 2,
      "name": "Rock_Runic_Cobble"
    },
    {
      "x": -14,
      "y": 4,
      "z": 2,
      "name": "Rock_Runic_Cobble"
    },
    {
      "x": -14,
      "y": 5,
      "z": 2,
      "name": "Rock_Runic_Cobble_Half"
    },
    {
      "x": -14,
      "y": 0,
      "z": 3,
      "name": "Rock_Runic_Brick"
    },
    {
      "x": -14,
      "y": 1,
      "z": 3,
      "name": "Rock_Runic_Cobble"
    },
    {
      "x": -14,
      "y": 2,
      "z": 3,
      "name": "Rock_Runic_Cobble"
    },
    {
      "x": -14,
      "y": 3,
      "z": 3,
      "name": "Rock_Runic_Cobble"
    },
    {
      "x": -14,
      "y": 4,
      "z": 3,
      "name": "Rock_Runic_Cobble"
    },
    {
      "x": -14,
      "y": 5,
      "z": 3,
      "name": "Rock_Runic_Cobble_Half"
    },
    {
      "x": -14,
      "y": 0,
      "z": 4,
      "name": "Rock_Runic_Brick",
      "rotation": 1
    },
    {
      "x": -14,
      "y": 1,
      "z": 4,
      "name": "Rock_Runic_Cobble",
      "rotation": 1
    },
    {
      "x": -14,
      "y": 2,
      "z": 4,
      "name": "Rock_Runic_Cobble",
      "rotation": 1
    },
    {
      "x": -14,
      "y": 3,
      "z": 4,
      "name": "Rock_Runic_Cobble",
      "rotation": 1
    },
    {
      "x": -14,
      "y": 4,
      "z": 4,
      "name": "Rock_Runic_Cobble",
      "rotation": 1
    },
    {
      "x": -14,
      "y": 5,
      "z": 4,
      "name": "Rock_Runic_Cobble_Half",
      "rotation": 1
    },
    {
      "x": -14,
      "y": 0,
      "z": 5,
      "name": "Rock_Runic_Brick",
      "rotation": 1
    },
    {
      "x": -14,
      "y": 1,
      "z": 5,
      "name": "Rock_Runic_Cobble",
      "rotation": 1
    },
    {
      "x": -14,
      "y": 2,
      "z": 5,
      "name": "Rock_Runic_Cobble",
      "rotation": 1
    },
    {
      "x": -14,
      "y": 3,
      "z": 5,
      "name": "Rock_Runic_Cobble",
      "rotation": 1
    },
    {
      "x": -14,
      "y": 4,
      "z": 5,
      "name": "Rock_Runic_Cobble",
      "rotation": 1
    },
    {
      "x": -14,
      "y": 5,
      "z": 5,
      "name": "Rock_Runic_Cobble_Half",
      "rotation": 1
    },
    {
      "x": -14,
      "y": 0,
      "z": 6,
      "name": "Rock_Runic_Brick",
      "rotation": 1
    },
    {
      "x": -14,
      "y": 0,
      "z": 7,
      "name": "Rock_Runic_Brick",
      "rotation": 1
    },
    {
      "x": -14,
      "y": 0,
      "z": 8,
      "name": "Rock_Runic_Brick",
      "rotation": 1
    },
    {
      "x": -14,
      "y": 0,
      "z": 9,
      "name": "Rock_Runic_Brick",
      "rotation": 1
    },
    {
      "x": -14,
      "y": 0,
      "z": 10,
      "name": "Rock_Runic_Brick",
      "rotation": 2
    },
    {
      "x": -14,
      "y": 0,
      "z": 11,
      "name": "Rock_Runic_Brick",
      "rotation": 2
    },
    {
      "x": -14,
      "y": 0,
      "z": 12,
      "name": "Rock_Runic_Brick",
      "rotation": 2
    },
    {
      "x": -14,
      "y": 0,
      "z": 13,
      "name": "Rock_Runic_Brick",
      "rotation": 2
    },
    {
      "x": -14,
      "y": 0,
      "z": 14,
      "name": "Rock_Runic_Brick",
      "rotation": 2
    },
    {
      "x": -14,
      "y": 1,
      "z": 14,
      "name": "Rock_Runic_Cobble",
      "rotation": 2
    },
    {
      "x": -14,
      "y": 2,
      "z": 14,
      "name": "Rock_Runic_Cobble",
      "rotation": 2
    },
    {
      "x": -14,
      "y": 3,
      "z": 14,
      "name": "Rock_Runic_Cobble",
      "rotation": 2
    },
    {
      "x": -14,
      "y": 4,
      "z": 14,
      "name": "Rock_Runic_Cobble",
      "rotation": 2
    },
    {
      "x": -14,
      "y": 5,
      "z": 14,
      "name": "Rock_Runic_Cobble_Half",
      "rotation": 2
    },
    {
      "x": -14,
      "y": 0,
      "z": 15,
      "name": "Rock_Runic_Brick",
      "rotation": 2
    },
    {
      "x": -14,
      "y": 1,
      "z": 15,
      "name": "Rock_Runic_Cobble",
      "rotation": 2
    },
    {
      "x": -14,
      "y": 2,
      "z": 15,
      "name": "Rock_Runic_Cobble",
      "rotation": 2
    },
    {
      "x": -14,
      "y": 3,
      "z": 15,
      "name": "Rock_Runic_Cobble",
      "rotation": 2
    },
    {
      "x": -14,
      "y": 4,
      "z": 15,
      "name": "Rock_Runic_Cobble",
      "rotation": 2
    },
    {
      "x": -14,
      "y": 5,
      "z": 15,
      "name": "Rock_Runic_Cobble_Half",
      "rotation": 2
    },
    {
      "x": -14,
      "y": 0,
      "z": 16,
      "name": "Soil_Grass"
    },
    {
      "x": -13,
      "y": 0,
      "z": -15,
      "name": "Soil_Grass"
    },
    {
      "x": -13,
      "y": 0,
      "z": -14,
      "name": "Rock_Runic_Brick",
      "rotation": 1
    },
    {
      "x": -13,
      "y": 1,
      "z": -14,
      "name": "Rock_Runic_Cobble",
      "rotation": 1
    },
    {
      "x": -13,
      "y": 2,
      "z": -14,
      "name": "Rock_Runic_Cobble",
      "rotation": 1
    },
    {
      "x": -13,
      "y": 3,
      "z": -14,
      "name": "Rock_Runic_Cobble",
      "rotation": 1
    },
    {
      "x": -13,
      "y": 4,
      "z": -14,
      "name": "Rock_Runic_Cobble",
      "rotation": 1
    },
    {
      "x": -13,
      "y": 5,
      "z": -14,
      "name": "Rock_Runic_Cobble_Half",
      "rotation": 1
    },
    {
      "x": -13,
      "y": 0,
      "z": -13,
      "name": "Rock_Runic_Brick",
      "rotation": 1
    },
    {
      "x": -13,
      "y": 1,
      "z": -13,
      "name": "Rock_Runic_Cobble",
      "rotation": 1
    },
    {
      "x": -13,
      "y": 2,
      "z": -13,
      "name": "Rock_Runic_Cobble",
      "rotation": 1
    },
    {
      "x": -13,
      "y": 3,
      "z": -13,
      "name": "Rock_Runic_Cobble",
      "rotation": 1
    },
    {
      "x": -13,
      "y": 4,
      "z": -13,
      "name": "Rock_Runic_Cobble",
      "rotation": 1
    },
    {
      "x": -13,
      "y": 5,
      "z": -13,
      "name": "Rock_Runic_Cobble_Half",
      "rotation": 1
    },
    {
      "x": -13,
      "y": 0,
      "z": -12,
      "name": "Rock_Runic_Brick",
      "rotation": 1
    },
    {
      "x": -13,
      "y": 0,
      "z": -11,
      "name": "Rock_Runic_Brick",
      "rotation": 1
    },
    {
      "x": -13,
      "y": 0,
      "z": -10,
      "name": "Rock_Runic_Brick",
      "rotation": 1
    },
    {
      "x": -13,
      "y": 1,
      "z": -10,
      "name": "Rock_Runic_Cobble",
      "rotation": 1
    },
    {
      "x": -13,
      "y": 2,
      "z": -10,
      "name": "Rock_Runic_Cobble",
      "rotation": 1
    },
    {
      "x": -13,
      "y": 3,
      "z": -10,
      "name": "Rock_Runic_Cobble",
      "rotation": 1
    },
    {
      "x": -13,
      "y": 4,
      "z": -10,
      "name": "Rock_Runic_Cobble",
      "rotation": 1
    },
    {
      "x": -13,
      "y": 5,
      "z": -10,
      "name": "Rock_Runic_Cobble_Half",
      "rotation": 1
    },
    {
      "x": -13,
      "y": 0,
      "z": -9,
      "name": "Rock_Runic_Brick",
      "rotation": 1
    },
    {
      "x": -13,
      "y": 1,
      "z": -9,
      "name": "Rock_Runic_Cobble",
      "rotation": 1
    },
    {
      "x": -13,
      "y": 2,
      "z": -9,
      "name": "Rock_Runic_Cobble",
      "rotation": 1
    },
    {
      "x": -13,
      "y": 3,
      "z": -9,
      "name": "Rock_Runic_Cobble",
      "rotation": 1
    },
    {
      "x": -13,
      "y": 4,
      "z": -9,
      "name": "Rock_Runic_Cobble",
      "rotation": 1
    },
    {
      "x": -13,
      "y": 5,
      "z": -9,
      "name": "Rock_Runic_Cobble_Half",
      "rotation": 1
    },
    {
      "x": -13,
      "y": 0,
      "z": -8,
      "name": "Rock_Runic_Brick",
      "rotation": 2
    },
    {
      "x": -13,
      "y": 1,
      "z": -8,
      "name": "Rock_Runic_Cobble",
      "rotation": 2
    },
    {
      "x": -13,
      "y": 2,
      "z": -8,
      "name": "Rock_Runic_Cobble",
      "rotation": 2
    },
    {
      "x": -13,
      "y": 3,
      "z": -8,
      "name": "Rock_Runic_Cobble",
      "rotation": 2
    },
    {
      "x": -13,
      "y": 4,
      "z": -8,
      "name": "Rock_Runic_Cobble",
      "rotation": 2
    },
    {
      "x": -13,
      "y": 5,
      "z": -8,
      "name": "Rock_Runic_Cobble_Half",
      "rotation": 2
    },
    {
      "x": -13,
      "y": 0,
      "z": -7,
      "name": "Rock_Runic_Brick",
      "rotation": 2
    },
    {
      "x": -13,
      "y": 1,
      "z": -7,
      "name": "Rock_Runic_Cobble",
      "rotation": 2
    },
    {
      "x": -13,
      "y": 2,
      "z": -7,
      "name": "Rock_Runic_Cobble",
      "rotation": 2
    },
    {
      "x": -13,
      "y": 3,
      "z": -7,
      "name": "Rock_Runic_Cobble",
      "rotation": 2
    },
    {
      "x": -13,
      "y": 4,
      "z": -7,
      "name": "Rock_Runic_Cobble",
      "rotation": 2
    },
    {
      "x": -13,
      "y": 5,
      "z": -7,
      "name": "Rock_Runic_Cobble_Half",
      "rotation": 2
    },
    {
      "x": -13,
      "y": 0,
      "z": -6,
      "name": "Rock_Runic_Brick",
      "rotation": 2
    },
    {
      "x": -13,
      "y": 0,
      "z": -5,
      "name": "Rock_Runic_Brick",
      "rotation": 2
    },
    {
      "x": -13,
      "y": 0,
      "z": -4,
      "name": "Rock_Runic_Brick",
      "rotation": 2
    },
    {
      "x": -13,
      "y": 1,
      "z": -4,
      "name": "Rock_Runic_Cobble",
      "rotation": 2
    },
    {
      "x": -13,
      "y": 2,
      "z": -4,
      "name": "Rock_Runic_Cobble",
      "rotation": 2
    },
    {
      "x": -13,
      "y": 3,
      "z": -4,
      "name": "Rock_Runic_Cobble",
      "rotation": 2
    },
    {
      "x": -13,
      "y": 4,
      "z": -4,
      "name": "Rock_Runic_Cobble",
      "rotation": 2
    },
    {
      "x": -13,
      "y": 5,
      "z": -4,
      "name": "Rock_Runic_Cobble_Half",
      "rotation": 2
    },
    {
      "x": -13,
      "y": 0,
      "z": -3,
      "name": "Rock_Runic_Brick",
      "rotation": 2
    },
    {
      "x": -13,
      "y": 1,
      "z": -3,
      "name": "Rock_Runic_Cobble",
      "rotation": 2
    },
    {
      "x": -13,
      "y": 2,
      "z": -3,
      "name": "Rock_Runic_Cobble",
      "rotation": 2
    },
    {
      "x": -13,
      "y": 3,
      "z": -3,
      "name": "Rock_Runic_Cobble",
      "rotation": 2
    },
    {
      "x": -13,
      "y": 4,
      "z": -3,
      "name": "Rock_Runic_Cobble",
      "rotation": 2
    },
    {
      "x": -13,
      "y": 5,
      "z": -3,
      "name": "Rock_Runic_Cobble_Half",
      "rotation": 2
    },
    {
      "x": -13,
      "y": 0,
      "z": -2,
      "name": "Rock_Runic_Brick"
    },
    {
      "x": -13,
      "y": 1,
      "z": -2,
      "name": "Rock_Runic_Cobble"
    },
    {
      "x": -13,
      "y": 2,
      "z": -2,
      "name": "Rock_Runic_Cobble"
    },
    {
      "x": -13,
      "y": 3,
      "z": -2,
      "name": "Rock_Runic_Cobble"
    },
    {
      "x": -13,
      "y": 4,
      "z": -2,
      "name": "Rock_Runic_Cobble"
    },
    {
      "x": -13,
      "y": 5,
      "z": -2,
      "name": "Rock_Runic_Cobble_Half"
    },
    {
      "x": -13,
      "y": 0,
      "z": -1,
      "name": "Rock_Runic_Brick"
    },
    {
      "x": -13,
      "y": 1,
      "z": -1,
      "name": "Rock_Runic_Cobble"
    },
    {
      "x": -13,
      "y": 2,
      "z": -1,
      "name": "Rock_Runic_Cobble"
    },
    {
      "x": -13,
      "y": 3,
      "z": -1,
      "name": "Rock_Runic_Cobble"
    },
    {
      "x": -13,
      "y": 4,
      "z": -1,
      "name": "Rock_Runic_Cobble"
    },
    {
      "x": -13,
      "y": 5,
      "z": -1,
      "name": "Rock_Runic_Cobble_Half"
    },
    {
      "x": -13,
      "y": 0,
      "z": 0,
      "name": "Rock_Runic_Brick"
    },
    {
      "x": -13,
      "y": 0,
      "z": 1,
      "name": "Rock_Runic_Brick"
    },
    {
      "x": -13,
      "y": 0,
      "z": 2,
      "name": "Rock_Runic_Brick"
    },
    {
      "x": -13,
      "y": 1,
      "z": 2,
      "name": "Rock_Runic_Cobble"
    },
    {
      "x": -13,
      "y": 2,
      "z": 2,
      "name": "Rock_Runic_Cobble"
    },
    {
      "x": -13,
      "y": 3,
      "z": 2,
      "name": "Rock_Runic_Cobble"
    },
    {
      "x": -13,
      "y": 4,
      "z": 2,
      "name": "Rock_Runic_Cobble"
    },
    {
      "x": -13,
      "y": 5,
      "z": 2,
      "name": "Rock_Runic_Cobble_Half"
    },
    {
      "x": -13,
      "y": 0,
      "z": 3,
      "name": "Rock_Runic_Brick"
    },
    {
      "x": -13,
      "y": 1,
      "z": 3,
      "name": "Rock_Runic_Cobble"
    },
    {
      "x": -13,
      "y": 2,
      "z": 3,
      "name": "Rock_Runic_Cobble"
    },
    {
      "x": -13,
      "y": 3,
      "z": 3,
      "name": "Rock_Runic_Cobble"
    },
    {
      "x": -13,
      "y": 4,
      "z": 3,
      "name": "Rock_Runic_Cobble"
    },
    {
      "x": -13,
      "y": 5,
      "z": 3,
      "name": "Rock_Runic_Cobble_Half"
    },
    {
      "x": -13,
      "y": 0,
      "z": 4,
      "name": "Rock_Runic_Brick",
      "rotation": 1
    },
    {
      "x": -13,
      "y": 1,
      "z": 4,
      "name": "Rock_Runic_Cobble",
      "rotation": 1
    },
    {
      "x": -13,
      "y": 2,
      "z": 4,
      "name": "Rock_Runic_Cobble",
      "rotation": 1
    },
    {
      "x": -13,
      "y": 3,
      "z": 4,
      "name": "Rock_Runic_Cobble",
      "rotation": 1
    },
    {
      "x": -13,
      "y": 4,
      "z": 4,
      "name": "Rock_Runic_Cobble",
      "rotation": 1
    },
    {
      "x": -13,
      "y": 5,
      "z": 4,
      "name": "Rock_Runic_Cobble_Half",
      "rotation": 1
    },
    {
      "x": -13,
      "y": 0,
      "z": 5,
      "name": "Rock_Runic_Brick",
      "rotation": 1
    },
    {
      "x": -13,
      "y": 1,
      "z": 5,
      "name": "Rock_Runic_Cobble",
      "rotation": 1
    },
    {
      "x": -13,
      "y": 2,
      "z": 5,
      "name": "Rock_Runic_Cobble",
      "rotation": 1
    },
    {
      "x": -13,
      "y": 3,
      "z": 5,
      "name": "Rock_Runic_Cobble",
      "rotation": 1
    },
    {
      "x": -13,
      "y": 4,
      "z": 5,
      "name": "Rock_Runic_Cobble",
      "rotation": 1
    },
    {
      "x": -13,
      "y": 5,
      "z": 5,
      "name": "Rock_Runic_Cobble_Half",
      "rotation": 1
    },
    {
      "x": -13,
      "y": 0,
      "z": 6,
      "name": "Rock_Runic_Brick",
      "rotation": 1
    },
    {
      "x": -13,
      "y": 0,
      "z": 7,
      "name": "Rock_Runic_Brick",
      "rotation": 1
    },
    {
      "x": -13,
      "y": 0,
      "z": 8,
      "name": "Rock_Runic_Brick",
      "rotation": 1
    },
    {
      "x": -13,
      "y": 1,
      "z": 8,
      "name": "Rock_Runic_Cobble",
      "rotation": 1
    },
    {
      "x": -13,
      "y": 2,
      "z": 8,
      "name": "Rock_Runic_Cobble",
      "rotation": 1
    },
    {
      "x": -13,
      "y": 3,
      "z": 8,
      "name": "Rock_Runic_Cobble",
      "rotation": 1
    },
    {
      "x": -13,
      "y": 4,
      "z": 8,
      "name": "Rock_Runic_Cobble",
      "rotation": 1
    },
    {
      "x": -13,
      "y": 5,
      "z": 8,
      "name": "Rock_Runic_Cobble_Half",
      "rotation": 1
    },
    {
      "x": -13,
      "y": 0,
      "z": 9,
      "name": "Rock_Runic_Brick",
      "rotation": 1
    },
    {
      "x": -13,
      "y": 1,
      "z": 9,
      "name": "Rock_Runic_Cobble",
      "rotation": 1
    },
    {
      "x": -13,
      "y": 2,
      "z": 9,
      "name": "Rock_Runic_Cobble",
      "rotation": 1
    },
    {
      "x": -13,
      "y": 3,
      "z": 9,
      "name": "Rock_Runic_Cobble",
      "rotation": 1
    },
    {
      "x": -13,
      "y": 4,
      "z": 9,
      "name": "Rock_Runic_Cobble",
      "rotation": 1
    },
    {
      "x": -13,
      "y": 5,
      "z": 9,
      "name": "Rock_Runic_Cobble_Half",
      "rotation": 1
    },
    {
      "x": -13,
      "y": 0,
      "z": 10,
      "name": "Rock_Runic_Brick",
      "rotation": 2
    },
    {
      "x": -13,
      "y": 1,
      "z": 10,
      "name": "Rock_Runic_Cobble",
      "rotation": 2
    },
    {
      "x": -13,
      "y": 2,
      "z": 10,
      "name": "Rock_Runic_Cobble",
      "rotation": 2
    },
    {
      "x": -13,
      "y": 3,
      "z": 10,
      "name": "Rock_Runic_Cobble",
      "rotation": 2
    },
    {
      "x": -13,
      "y": 4,
      "z": 10,
      "name": "Rock_Runic_Cobble",
      "rotation": 2
    },
    {
      "x": -13,
      "y": 5,
      "z": 10,
      "name": "Rock_Runic_Cobble_Half",
      "rotation": 2
    },
    {
      "x": -13,
      "y": 0,
      "z": 11,
      "name": "Rock_Runic_Brick",
      "rotation": 2
    },
    {
      "x": -13,
      "y": 1,
      "z": 11,
      "name": "Rock_Runic_Cobble",
      "rotation": 2
    },
    {
      "x": -13,
      "y": 2,
      "z": 11,
      "name": "Rock_Runic_Cobble",
      "rotation": 2
    },
    {
      "x": -13,
      "y": 3,
      "z": 11,
      "name": "Rock_Runic_Cobble",
      "rotation": 2
    },
    {
      "x": -13,
      "y": 4,
      "z": 11,
      "name": "Rock_Runic_Cobble",
      "rotation": 2
    },
    {
      "x": -13,
      "y": 5,
      "z": 11,
      "name": "Rock_Runic_Cobble_Half",
      "rotation": 2
    },
    {
      "x": -13,
      "y": 0,
      "z": 12,
      "name": "Rock_Runic_Brick",
      "rotation": 2
    },
    {
      "x": -13,
      "y": 0,
      "z": 13,
      "name": "Rock_Runic_Brick",
      "rotation": 2
    },
    {
      "x": -13,
      "y": 0,
      "z": 14,
      "name": "Rock_Runic_Brick",
      "rotation": 2
    },
    {
      "x": -13,
      "y": 1,
      "z": 14,
      "name": "Rock_Runic_Cobble",
      "rotation": 2
    },
    {
      "x": -13,
      "y": 2,
      "z": 14,
      "name": "Rock_Runic_Cobble",
      "rotation": 2
    },
    {
      "x": -13,
      "y": 3,
      "z": 14,
      "name": "Rock_Runic_Cobble",
      "rotation": 2
    },
    {
      "x": -13,
      "y": 4,
      "z": 14,
      "name": "Rock_Runic_Cobble",
      "rotation": 2
    },
    {
      "x": -13,
      "y": 5,
      "z": 14,
      "name": "Rock_Runic_Cobble_Half",
      "rotation": 2
    },
    {
      "x": -13,
      "y": 0,
      "z": 15,
      "name": "Rock_Runic_Brick",
      "rotation": 2
    },
    {
      "x": -13,
      "y": 1,
      "z": 15,
      "name": "Rock_Runic_Cobble",
      "rotation": 2
    },
    {
      "x": -13,
      "y": 2,
      "z": 15,
      "name": "Rock_Runic_Cobble",
      "rotation": 2
    },
    {
      "x": -13,
      "y": 3,
      "z": 15,
      "name": "Rock_Runic_Cobble",
      "rotation": 2
    },
    {
      "x": -13,
      "y": 4,
      "z": 15,
      "name": "Rock_Runic_Cobble",
      "rotation": 2
    },
    {
      "x": -13,
      "y": 5,
      "z": 15,
      "name": "Rock_Runic_Cobble_Half",
      "rotation": 2
    },
    {
      "x": -13,
      "y": 0,
      "z": 16,
      "name": "Soil_Grass"
    },
    {
      "x": -12,
      "y": 0,
      "z": -15,
      "name": "Soil_Grass"
    },
    {
      "x": -12,
      "y": 0,
      "z": -14,
      "name": "Rock_Runic_Brick",
      "rotation": 1
    },
    {
      "x": -12,
      "y": 1,
      "z": -14,
      "name": "Rock_Runic_Cobble",
      "rotation": 1
    },
    {
      "x": -12,
      "y": 2,
      "z": -14,
      "name": "Rock_Runic_Cobble",
      "rotation": 1
    },
    {
      "x": -12,
      "y": 3,
      "z": -14,
      "name": "Rock_Runic_Cobble",
      "rotation": 1
    },
    {
      "x": -12,
      "y": 4,
      "z": -14,
      "name": "Rock_Runic_Cobble",
      "rotation": 1
    },
    {
      "x": -12,
      "y": 5,
      "z": -14,
      "name": "Rock_Runic_Cobble_Half",
      "rotation": 1
    },
    {
      "x": -12,
      "y": 0,
      "z": -13,
      "name": "Rock_Runic_Brick",
      "rotation": 1
    },
    {
      "x": -12,
      "y": 1,
      "z": -13,
      "name": "Rock_Runic_Cobble",
      "rotation": 1
    },
    {
      "x": -12,
      "y": 2,
      "z": -13,
      "name": "Rock_Runic_Cobble",
      "rotation": 1
    },
    {
      "x": -12,
      "y": 3,
      "z": -13,
      "name": "Rock_Runic_Cobble",
      "rotation": 1
    },
    {
      "x": -12,
      "y": 4,
      "z": -13,
      "name": "Rock_Runic_Cobble",
      "rotation": 1
    },
    {
      "x": -12,
      "y": 5,
      "z": -13,
      "name": "Rock_Runic_Cobble_Half",
      "rotation": 1
    },
    {
      "x": -12,
      "y": 0,
      "z": -12,
      "name": "Rock_Runic_Brick",
      "rotation": 1
    },
    {
      "x": -12,
      "y": 0,
      "z": -11,
      "name": "Rock_Runic_Brick",
      "rotation": 1
    },
    {
      "x": -12,
      "y": 0,
      "z": -10,
      "name": "Rock_Runic_Brick",
      "rotation": 1
    },
    {
      "x": -12,
      "y": 1,
      "z": -10,
      "name": "Rock_Runic_Cobble",
      "rotation": 1
    },
    {
      "x": -12,
      "y": 2,
      "z": -10,
      "name": "Rock_Runic_Cobble",
      "rotation": 1
    },
    {
      "x": -12,
      "y": 3,
      "z": -10,
      "name": "Rock_Runic_Cobble",
      "rotation": 1
    },
    {
      "x": -12,
      "y": 4,
      "z": -10,
      "name": "Rock_Runic_Cobble",
      "rotation": 1
    },
    {
      "x": -12,
      "y": 5,
      "z": -10,
      "name": "Rock_Runic_Cobble_Half",
      "rotation": 1
    },
    {
      "x": -12,
      "y": 0,
      "z": -9,
      "name": "Rock_Runic_Brick",
      "rotation": 1
    },
    {
      "x": -12,
      "y": 1,
      "z": -9,
      "name": "Rock_Runic_Cobble",
      "rotation": 1
    },
    {
      "x": -12,
      "y": 2,
      "z": -9,
      "name": "Rock_Runic_Cobble",
      "rotation": 1
    },
    {
      "x": -12,
      "y": 3,
      "z": -9,
      "name": "Rock_Runic_Cobble",
      "rotation": 1
    },
    {
      "x": -12,
      "y": 4,
      "z": -9,
      "name": "Rock_Runic_Cobble",
      "rotation": 1
    },
    {
      "x": -12,
      "y": 5,
      "z": -9,
      "name": "Rock_Runic_Cobble_Half",
      "rotation": 1
    },
    {
      "x": -12,
      "y": 0,
      "z": -8,
      "name": "Rock_Runic_Brick",
      "rotation": 2
    },
    {
      "x": -12,
      "y": 1,
      "z": -8,
      "name": "Rock_Runic_Cobble",
      "rotation": 2
    },
    {
      "x": -12,
      "y": 2,
      "z": -8,
      "name": "Rock_Runic_Cobble",
      "rotation": 2
    },
    {
      "x": -12,
      "y": 3,
      "z": -8,
      "name": "Rock_Runic_Cobble",
      "rotation": 2
    },
    {
      "x": -12,
      "y": 4,
      "z": -8,
      "name": "Rock_Runic_Cobble",
      "rotation": 2
    },
    {
      "x": -12,
      "y": 5,
      "z": -8,
      "name": "Rock_Runic_Cobble_Half",
      "rotation": 2
    },
    {
      "x": -12,
      "y": 0,
      "z": -7,
      "name": "Rock_Runic_Brick",
      "rotation": 2
    },
    {
      "x": -12,
      "y": 1,
      "z": -7,
      "name": "Rock_Runic_Cobble",
      "rotation": 2
    },
    {
      "x": -12,
      "y": 2,
      "z": -7,
      "name": "Rock_Runic_Cobble",
      "rotation": 2
    },
    {
      "x": -12,
      "y": 3,
      "z": -7,
      "name": "Rock_Runic_Cobble",
      "rotation": 2
    },
    {
      "x": -12,
      "y": 4,
      "z": -7,
      "name": "Rock_Runic_Cobble",
      "rotation": 2
    },
    {
      "x": -12,
      "y": 5,
      "z": -7,
      "name": "Rock_Runic_Cobble_Half",
      "rotation": 2
    },
    {
      "x": -12,
      "y": 0,
      "z": -6,
      "name": "Rock_Runic_Brick",
      "rotation": 2
    },
    {
      "x": -12,
      "y": 0,
      "z": -5,
      "name": "Rock_Runic_Brick",
      "rotation": 2
    },
    {
      "x": -12,
      "y": 0,
      "z": -4,
      "name": "Rock_Runic_Brick",
      "rotation": 2
    },
    {
      "x": -12,
      "y": 1,
      "z": -4,
      "name": "Rock_Runic_Cobble",
      "rotation": 2
    },
    {
      "x": -12,
      "y": 2,
      "z": -4,
      "name": "Rock_Runic_Cobble",
      "rotation": 2
    },
    {
      "x": -12,
      "y": 3,
      "z": -4,
      "name": "Rock_Runic_Cobble",
      "rotation": 2
    },
    {
      "x": -12,
      "y": 4,
      "z": -4,
      "name": "Rock_Runic_Cobble",
      "rotation": 2
    },
    {
      "x": -12,
      "y": 5,
      "z": -4,
      "name": "Rock_Runic_Cobble_Half",
      "rotation": 2
    },
    {
      "x": -12,
      "y": 0,
      "z": -3,
      "name": "Rock_Runic_Brick",
      "rotation": 2
    },
    {
      "x": -12,
      "y": 1,
      "z": -3,
      "name": "Rock_Runic_Cobble",
      "rotation": 2
    },
    {
      "x": -12,
      "y": 2,
      "z": -3,
      "name": "Rock_Runic_Cobble",
      "rotation": 2
    },
    {
      "x": -12,
      "y": 3,
      "z": -3,
      "name": "Rock_Runic_Cobble",
      "rotation": 2
    },
    {
      "x": -12,
      "y": 4,
      "z": -3,
      "name": "Rock_Runic_Cobble",
      "rotation": 2
    },
    {
      "x": -12,
      "y": 5,
      "z": -3,
      "name": "Rock_Runic_Cobble_Half",
      "rotation": 2
    },
    {
      "x": -12,
      "y": 0,
      "z": -2,
      "name": "Rock_Runic_Brick"
    },
    {
      "x": -12,
      "y": 1,
      "z": -2,
      "name": "Rock_Runic_Cobble"
    },
    {
      "x": -12,
      "y": 2,
      "z": -2,
      "name": "Rock_Runic_Cobble"
    },
    {
      "x": -12,
      "y": 3,
      "z": -2,
      "name": "Rock_Runic_Cobble"
    },
    {
      "x": -12,
      "y": 4,
      "z": -2,
      "name": "Rock_Runic_Cobble"
    },
    {
      "x": -12,
      "y": 5,
      "z": -2,
      "name": "Rock_Runic_Cobble_Half"
    },
    {
      "x": -12,
      "y": 0,
      "z": -1,
      "name": "Rock_Runic_Brick"
    },
    {
      "x": -12,
      "y": 1,
      "z": -1,
      "name": "Rock_Runic_Cobble"
    },
    {
      "x": -12,
      "y": 2,
      "z": -1,
      "name": "Rock_Runic_Cobble"
    },
    {
      "x": -12,
      "y": 3,
      "z": -1,
      "name": "Rock_Runic_Cobble"
    },
    {
      "x": -12,
      "y": 4,
      "z": -1,
      "name": "Rock_Runic_Cobble"
    },
    {
      "x": -12,
      "y": 5,
      "z": -1,
      "name": "Rock_Runic_Cobble_Half"
    },
    {
      "x": -12,
      "y": 0,
      "z": 0,
      "name": "Rock_Runic_Brick"
    },
    {
      "x": -12,
      "y": 0,
      "z": 1,
      "name": "Rock_Runic_Brick"
    },
    {
      "x": -12,
      "y": 0,
      "z": 2,
      "name": "Rock_Runic_Brick"
    },
    {
      "x": -12,
      "y": 1,
      "z": 2,
      "name": "Rock_Runic_Cobble"
    },
    {
      "x": -12,
      "y": 2,
      "z": 2,
      "name": "Rock_Runic_Cobble"
    },
    {
      "x": -12,
      "y": 3,
      "z": 2,
      "name": "Rock_Runic_Cobble"
    },
    {
      "x": -12,
      "y": 4,
      "z": 2,
      "name": "Rock_Runic_Cobble"
    },
    {
      "x": -12,
      "y": 5,
      "z": 2,
      "name": "Rock_Runic_Cobble_Half"
    },
    {
      "x": -12,
      "y": 0,
      "z": 3,
      "name": "Rock_Runic_Brick"
    },
    {
      "x": -12,
      "y": 1,
      "z": 3,
      "name": "Rock_Runic_Cobble"
    },
    {
      "x": -12,
      "y": 2,
      "z": 3,
      "name": "Rock_Runic_Cobble"
    },
    {
      "x": -12,
      "y": 3,
      "z": 3,
      "name": "Rock_Runic_Cobble"
    },
    {
      "x": -12,
      "y": 4,
      "z": 3,
      "name": "Rock_Runic_Cobble"
    },
    {
      "x": -12,
      "y": 5,
      "z": 3,
      "name": "Rock_Runic_Cobble_Half"
    },
    {
      "x": -12,
      "y": 0,
      "z": 4,
      "name": "Rock_Runic_Brick",
      "rotation": 1
    },
    {
      "x": -12,
      "y": 1,
      "z": 4,
      "name": "Rock_Runic_Cobble",
      "rotation": 1
    },
    {
      "x": -12,
      "y": 2,
      "z": 4,
      "name": "Rock_Runic_Cobble",
      "rotation": 1
    },
    {
      "x": -12,
      "y": 3,
      "z": 4,
      "name": "Rock_Runic_Cobble",
      "rotation": 1
    },
    {
      "x": -12,
      "y": 4,
      "z": 4,
      "name": "Rock_Runic_Cobble",
      "rotation": 1
    },
    {
      "x": -12,
      "y": 5,
      "z": 4,
      "name": "Rock_Runic_Cobble_Half",
      "rotation": 1
    },
    {
      "x": -12,
      "y": 0,
      "z": 5,
      "name": "Rock_Runic_Brick",
      "rotation": 1
    },
    {
      "x": -12,
      "y": 1,
      "z": 5,
      "name": "Rock_Runic_Cobble",
      "rotation": 1
    },
    {
      "x": -12,
      "y": 2,
      "z": 5,
      "name": "Rock_Runic_Cobble",
      "rotation": 1
    },
    {
      "x": -12,
      "y": 3,
      "z": 5,
      "name": "Rock_Runic_Cobble",
      "rotation": 1
    },
    {
      "x": -12,
      "y": 4,
      "z": 5,
      "name": "Rock_Runic_Cobble",
      "rotation": 1
    },
    {
      "x": -12,
      "y": 5,
      "z": 5,
      "name": "Rock_Runic_Cobble_Half",
      "rotation": 1
    },
    {
      "x": -12,
      "y": 0,
      "z": 6,
      "name": "Rock_Runic_Brick",
      "rotation": 1
    },
    {
      "x": -12,
      "y": 1,
      "z": 6,
      "name": "Bench_Furniture",
      "filler": 992,
      "rotation": 3
    },
    {
      "x": -12,
      "y": 2,
      "z": 6,
      "name": "Bench_Furniture",
      "filler": 2016,
      "rotation": 3
    },
    {
      "x": -12,
      "y": 0,
      "z": 7,
      "name": "Rock_Runic_Brick",
      "rotation": 1
    },
    {
      "x": -12,
      "y": 1,
      "z": 7,
      "name": "Bench_Furniture",
      "components": {
        "Components": {
          "PlacedByInteraction": {
            "WhoPlacedUuid": {
              "$binary": "e9fJvv+uQbiAosZl4PkaIA==",
              "$type": "04"
            }
          },
          "BenchBlock": {
            "TierLevel": 1,
            "UpgradeItems": []
          }
        }
      },
      "rotation": 3
    },
    {
      "x": -12,
      "y": 2,
      "z": 7,
      "name": "Bench_Furniture",
      "filler": 1024,
      "rotation": 3
    },
    {
      "x": -12,
      "y": 0,
      "z": 8,
      "name": "Rock_Runic_Brick",
      "rotation": 1
    },
    {
      "x": -12,
      "y": 1,
      "z": 8,
      "name": "Rock_Runic_Cobble",
      "rotation": 1
    },
    {
      "x": -12,
      "y": 2,
      "z": 8,
      "name": "Rock_Runic_Cobble",
      "rotation": 1
    },
    {
      "x": -12,
      "y": 3,
      "z": 8,
      "name": "Rock_Runic_Cobble",
      "rotation": 1
    },
    {
      "x": -12,
      "y": 4,
      "z": 8,
      "name": "Rock_Runic_Cobble",
      "rotation": 1
    },
    {
      "x": -12,
      "y": 5,
      "z": 8,
      "name": "Rock_Runic_Cobble_Half",
      "rotation": 1
    },
    {
      "x": -12,
      "y": 0,
      "z": 9,
      "name": "Rock_Runic_Brick",
      "rotation": 1
    },
    {
      "x": -12,
      "y": 1,
      "z": 9,
      "name": "Rock_Runic_Cobble",
      "rotation": 1
    },
    {
      "x": -12,
      "y": 2,
      "z": 9,
      "name": "Rock_Runic_Cobble",
      "rotation": 1
    },
    {
      "x": -12,
      "y": 3,
      "z": 9,
      "name": "Rock_Runic_Cobble",
      "rotation": 1
    },
    {
      "x": -12,
      "y": 4,
      "z": 9,
      "name": "Rock_Runic_Cobble",
      "rotation": 1
    },
    {
      "x": -12,
      "y": 5,
      "z": 9,
      "name": "Rock_Runic_Cobble_Half",
      "rotation": 1
    },
    {
      "x": -12,
      "y": 0,
      "z": 10,
      "name": "Rock_Runic_Brick",
      "rotation": 2
    },
    {
      "x": -12,
      "y": 1,
      "z": 10,
      "name": "Rock_Runic_Cobble",
      "rotation": 2
    },
    {
      "x": -12,
      "y": 2,
      "z": 10,
      "name": "Rock_Runic_Cobble",
      "rotation": 2
    },
    {
      "x": -12,
      "y": 3,
      "z": 10,
      "name": "Rock_Runic_Cobble",
      "rotation": 2
    },
    {
      "x": -12,
      "y": 4,
      "z": 10,
      "name": "Rock_Runic_Cobble",
      "rotation": 2
    },
    {
      "x": -12,
      "y": 5,
      "z": 10,
      "name": "Rock_Runic_Cobble_Half",
      "rotation": 2
    },
    {
      "x": -12,
      "y": 0,
      "z": 11,
      "name": "Rock_Runic_Brick",
      "rotation": 2
    },
    {
      "x": -12,
      "y": 1,
      "z": 11,
      "name": "Rock_Runic_Cobble",
      "rotation": 2
    },
    {
      "x": -12,
      "y": 2,
      "z": 11,
      "name": "Rock_Runic_Cobble",
      "rotation": 2
    },
    {
      "x": -12,
      "y": 3,
      "z": 11,
      "name": "Rock_Runic_Cobble",
      "rotation": 2
    },
    {
      "x": -12,
      "y": 4,
      "z": 11,
      "name": "Rock_Runic_Cobble",
      "rotation": 2
    },
    {
      "x": -12,
      "y": 5,
      "z": 11,
      "name": "Rock_Runic_Cobble_Half",
      "rotation": 2
    },
    {
      "x": -12,
      "y": 0,
      "z": 12,
      "name": "Rock_Runic_Brick",
      "rotation": 2
    },
    {
      "x": -12,
      "y": 0,
      "z": 13,
      "name": "Rock_Runic_Brick",
      "rotation": 2
    },
    {
      "x": -12,
      "y": 0,
      "z": 14,
      "name": "Rock_Runic_Brick",
      "rotation": 2
    },
    {
      "x": -12,
      "y": 1,
      "z": 14,
      "name": "Rock_Runic_Cobble",
      "rotation": 2
    },
    {
      "x": -12,
      "y": 2,
      "z": 14,
      "name": "Rock_Runic_Cobble",
      "rotation": 2
    },
    {
      "x": -12,
      "y": 3,
      "z": 14,
      "name": "Rock_Runic_Cobble",
      "rotation": 2
    },
    {
      "x": -12,
      "y": 4,
      "z": 14,
      "name": "Rock_Runic_Cobble",
      "rotation": 2
    },
    {
      "x": -12,
      "y": 5,
      "z": 14,
      "name": "Rock_Runic_Cobble_Half",
      "rotation": 2
    },
    {
      "x": -12,
      "y": 0,
      "z": 15,
      "name": "Rock_Runic_Brick",
      "rotation": 2
    },
    {
      "x": -12,
      "y": 1,
      "z": 15,
      "name": "Rock_Runic_Cobble",
      "rotation": 2
    },
    {
      "x": -12,
      "y": 2,
      "z": 15,
      "name": "Rock_Runic_Cobble",
      "rotation": 2
    },
    {
      "x": -12,
      "y": 3,
      "z": 15,
      "name": "Rock_Runic_Cobble",
      "rotation": 2
    },
    {
      "x": -12,
      "y": 4,
      "z": 15,
      "name": "Rock_Runic_Cobble",
      "rotation": 2
    },
    {
      "x": -12,
      "y": 5,
      "z": 15,
      "name": "Rock_Runic_Cobble_Half",
      "rotation": 2
    },
    {
      "x": -12,
      "y": 0,
      "z": 16,
      "name": "Soil_Grass"
    },
    {
      "x": -11,
      "y": 0,
      "z": -15,
      "name": "Soil_Grass"
    },
    {
      "x": -11,
      "y": 0,
      "z": -14,
      "name": "Rock_Runic_Brick",
      "rotation": 3
    },
    {
      "x": -11,
      "y": 1,
      "z": -14,
      "name": "Rock_Runic_Cobble",
      "rotation": 3
    },
    {
      "x": -11,
      "y": 2,
      "z": -14,
      "name": "Rock_Runic_Cobble",
      "rotation": 3
    },
    {
      "x": -11,
      "y": 3,
      "z": -14,
      "name": "Rock_Runic_Cobble",
      "rotation": 3
    },
    {
      "x": -11,
      "y": 4,
      "z": -14,
      "name": "Rock_Runic_Cobble",
      "rotation": 3
    },
    {
      "x": -11,
      "y": 5,
      "z": -14,
      "name": "Rock_Runic_Cobble_Half",
      "rotation": 3
    },
    {
      "x": -11,
      "y": 0,
      "z": -13,
      "name": "Rock_Runic_Brick",
      "rotation": 3
    },
    {
      "x": -11,
      "y": 1,
      "z": -13,
      "name": "Rock_Runic_Cobble",
      "rotation": 3
    },
    {
      "x": -11,
      "y": 2,
      "z": -13,
      "name": "Rock_Runic_Cobble",
      "rotation": 3
    },
    {
      "x": -11,
      "y": 3,
      "z": -13,
      "name": "Rock_Runic_Cobble",
      "rotation": 3
    },
    {
      "x": -11,
      "y": 4,
      "z": -13,
      "name": "Rock_Runic_Cobble",
      "rotation": 3
    },
    {
      "x": -11,
      "y": 5,
      "z": -13,
      "name": "Rock_Runic_Cobble_Half",
      "rotation": 3
    },
    {
      "x": -11,
      "y": 0,
      "z": -12,
      "name": "Rock_Runic_Brick",
      "rotation": 3
    },
    {
      "x": -11,
      "y": 0,
      "z": -11,
      "name": "Rock_Runic_Brick",
      "rotation": 3
    },
    {
      "x": -11,
      "y": 0,
      "z": -10,
      "name": "Rock_Runic_Brick",
      "rotation": 3
    },
    {
      "x": -11,
      "y": 1,
      "z": -10,
      "name": "Rock_Runic_Cobble",
      "rotation": 3
    },
    {
      "x": -11,
      "y": 2,
      "z": -10,
      "name": "Rock_Runic_Cobble",
      "rotation": 3
    },
    {
      "x": -11,
      "y": 3,
      "z": -10,
      "name": "Rock_Runic_Cobble",
      "rotation": 3
    },
    {
      "x": -11,
      "y": 4,
      "z": -10,
      "name": "Rock_Runic_Cobble",
      "rotation": 3
    },
    {
      "x": -11,
      "y": 5,
      "z": -10,
      "name": "Rock_Runic_Cobble_Half",
      "rotation": 3
    },
    {
      "x": -11,
      "y": 0,
      "z": -9,
      "name": "Rock_Runic_Brick",
      "rotation": 3
    },
    {
      "x": -11,
      "y": 1,
      "z": -9,
      "name": "Rock_Runic_Cobble",
      "rotation": 3
    },
    {
      "x": -11,
      "y": 2,
      "z": -9,
      "name": "Rock_Runic_Cobble",
      "rotation": 3
    },
    {
      "x": -11,
      "y": 3,
      "z": -9,
      "name": "Rock_Runic_Cobble",
      "rotation": 3
    },
    {
      "x": -11,
      "y": 4,
      "z": -9,
      "name": "Rock_Runic_Cobble",
      "rotation": 3
    },
    {
      "x": -11,
      "y": 5,
      "z": -9,
      "name": "Rock_Runic_Cobble_Half",
      "rotation": 3
    },
    {
      "x": -11,
      "y": 0,
      "z": -8,
      "name": "Rock_Runic_Brick"
    },
    {
      "x": -11,
      "y": 1,
      "z": -8,
      "name": "Rock_Runic_Cobble"
    },
    {
      "x": -11,
      "y": 2,
      "z": -8,
      "name": "Rock_Runic_Cobble"
    },
    {
      "x": -11,
      "y": 3,
      "z": -8,
      "name": "Rock_Runic_Cobble"
    },
    {
      "x": -11,
      "y": 4,
      "z": -8,
      "name": "Rock_Runic_Cobble"
    },
    {
      "x": -11,
      "y": 5,
      "z": -8,
      "name": "Rock_Runic_Cobble_Half"
    },
    {
      "x": -11,
      "y": 0,
      "z": -7,
      "name": "Rock_Runic_Brick"
    },
    {
      "x": -11,
      "y": 1,
      "z": -7,
      "name": "Rock_Runic_Cobble"
    },
    {
      "x": -11,
      "y": 2,
      "z": -7,
      "name": "Rock_Runic_Cobble"
    },
    {
      "x": -11,
      "y": 3,
      "z": -7,
      "name": "Rock_Runic_Cobble"
    },
    {
      "x": -11,
      "y": 4,
      "z": -7,
      "name": "Rock_Runic_Cobble"
    },
    {
      "x": -11,
      "y": 5,
      "z": -7,
      "name": "Rock_Runic_Cobble_Half"
    },
    {
      "x": -11,
      "y": 0,
      "z": -6,
      "name": "Rock_Runic_Brick"
    },
    {
      "x": -11,
      "y": 0,
      "z": -5,
      "name": "Rock_Runic_Brick"
    },
    {
      "x": -11,
      "y": 0,
      "z": -4,
      "name": "Rock_Runic_Brick"
    },
    {
      "x": -11,
      "y": 1,
      "z": -4,
      "name": "Rock_Runic_Cobble"
    },
    {
      "x": -11,
      "y": 2,
      "z": -4,
      "name": "Rock_Runic_Cobble"
    },
    {
      "x": -11,
      "y": 3,
      "z": -4,
      "name": "Rock_Runic_Cobble"
    },
    {
      "x": -11,
      "y": 4,
      "z": -4,
      "name": "Rock_Runic_Cobble"
    },
    {
      "x": -11,
      "y": 5,
      "z": -4,
      "name": "Rock_Runic_Cobble_Half"
    },
    {
      "x": -11,
      "y": 0,
      "z": -3,
      "name": "Rock_Runic_Brick"
    },
    {
      "x": -11,
      "y": 1,
      "z": -3,
      "name": "Rock_Runic_Cobble"
    },
    {
      "x": -11,
      "y": 2,
      "z": -3,
      "name": "Rock_Runic_Cobble"
    },
    {
      "x": -11,
      "y": 3,
      "z": -3,
      "name": "Rock_Runic_Cobble"
    },
    {
      "x": -11,
      "y": 4,
      "z": -3,
      "name": "Rock_Runic_Cobble"
    },
    {
      "x": -11,
      "y": 5,
      "z": -3,
      "name": "Rock_Runic_Cobble_Half"
    },
    {
      "x": -11,
      "y": 0,
      "z": -2,
      "name": "Rock_Runic_Brick"
    },
    {
      "x": -11,
      "y": 1,
      "z": -2,
      "name": "Rock_Runic_Cobble"
    },
    {
      "x": -11,
      "y": 2,
      "z": -2,
      "name": "Rock_Runic_Cobble"
    },
    {
      "x": -11,
      "y": 3,
      "z": -2,
      "name": "Rock_Runic_Cobble"
    },
    {
      "x": -11,
      "y": 4,
      "z": -2,
      "name": "Rock_Runic_Cobble"
    },
    {
      "x": -11,
      "y": 5,
      "z": -2,
      "name": "Rock_Runic_Cobble_Half"
    },
    {
      "x": -11,
      "y": 0,
      "z": -1,
      "name": "Rock_Runic_Brick"
    },
    {
      "x": -11,
      "y": 1,
      "z": -1,
      "name": "Rock_Runic_Cobble"
    },
    {
      "x": -11,
      "y": 2,
      "z": -1,
      "name": "Rock_Runic_Cobble"
    },
    {
      "x": -11,
      "y": 3,
      "z": -1,
      "name": "Rock_Runic_Cobble"
    },
    {
      "x": -11,
      "y": 4,
      "z": -1,
      "name": "Rock_Runic_Cobble"
    },
    {
      "x": -11,
      "y": 5,
      "z": -1,
      "name": "Rock_Runic_Cobble_Half"
    },
    {
      "x": -11,
      "y": 0,
      "z": 0,
      "name": "Rock_Runic_Brick"
    },
    {
      "x": -11,
      "y": 0,
      "z": 1,
      "name": "Rock_Runic_Brick"
    },
    {
      "x": -11,
      "y": 0,
      "z": 2,
      "name": "Rock_Runic_Brick"
    },
    {
      "x": -11,
      "y": 1,
      "z": 2,
      "name": "Rock_Runic_Cobble"
    },
    {
      "x": -11,
      "y": 2,
      "z": 2,
      "name": "Rock_Runic_Cobble"
    },
    {
      "x": -11,
      "y": 3,
      "z": 2,
      "name": "Rock_Runic_Cobble"
    },
    {
      "x": -11,
      "y": 4,
      "z": 2,
      "name": "Rock_Runic_Cobble"
    },
    {
      "x": -11,
      "y": 5,
      "z": 2,
      "name": "Rock_Runic_Cobble_Half"
    },
    {
      "x": -11,
      "y": 0,
      "z": 3,
      "name": "Rock_Runic_Brick"
    },
    {
      "x": -11,
      "y": 1,
      "z": 3,
      "name": "Rock_Runic_Cobble"
    },
    {
      "x": -11,
      "y": 2,
      "z": 3,
      "name": "Rock_Runic_Cobble"
    },
    {
      "x": -11,
      "y": 3,
      "z": 3,
      "name": "Rock_Runic_Cobble"
    },
    {
      "x": -11,
      "y": 4,
      "z": 3,
      "name": "Rock_Runic_Cobble"
    },
    {
      "x": -11,
      "y": 5,
      "z": 3,
      "name": "Rock_Runic_Cobble_Half"
    },
    {
      "x": -11,
      "y": 0,
      "z": 4,
      "name": "Rock_Runic_Brick",
      "rotation": 1
    },
    {
      "x": -11,
      "y": 1,
      "z": 4,
      "name": "Rock_Runic_Cobble",
      "rotation": 1
    },
    {
      "x": -11,
      "y": 2,
      "z": 4,
      "name": "Rock_Runic_Cobble",
      "rotation": 1
    },
    {
      "x": -11,
      "y": 3,
      "z": 4,
      "name": "Rock_Runic_Cobble",
      "rotation": 1
    },
    {
      "x": -11,
      "y": 4,
      "z": 4,
      "name": "Rock_Runic_Cobble",
      "rotation": 1
    },
    {
      "x": -11,
      "y": 5,
      "z": 4,
      "name": "Rock_Runic_Cobble_Half",
      "rotation": 1
    },
    {
      "x": -11,
      "y": 0,
      "z": 5,
      "name": "Rock_Runic_Brick",
      "rotation": 1
    },
    {
      "x": -11,
      "y": 1,
      "z": 5,
      "name": "Rock_Runic_Cobble",
      "rotation": 1
    },
    {
      "x": -11,
      "y": 2,
      "z": 5,
      "name": "Rock_Runic_Cobble",
      "rotation": 1
    },
    {
      "x": -11,
      "y": 3,
      "z": 5,
      "name": "Rock_Runic_Cobble",
      "rotation": 1
    },
    {
      "x": -11,
      "y": 4,
      "z": 5,
      "name": "Rock_Runic_Cobble",
      "rotation": 1
    },
    {
      "x": -11,
      "y": 5,
      "z": 5,
      "name": "Rock_Runic_Cobble_Half",
      "rotation": 1
    },
    {
      "x": -11,
      "y": 0,
      "z": 6,
      "name": "Rock_Runic_Brick",
      "rotation": 1
    },
    {
      "x": -11,
      "y": 1,
      "z": 6,
      "name": "Rock_Runic_Cobble",
      "rotation": 1
    },
    {
      "x": -11,
      "y": 2,
      "z": 6,
      "name": "Rock_Runic_Cobble",
      "rotation": 1
    },
    {
      "x": -11,
      "y": 3,
      "z": 6,
      "name": "Rock_Runic_Cobble",
      "rotation": 1
    },
    {
      "x": -11,
      "y": 4,
      "z": 6,
      "name": "Rock_Runic_Cobble",
      "rotation": 1
    },
    {
      "x": -11,
      "y": 5,
      "z": 6,
      "name": "Rock_Runic_Cobble_Half",
      "rotation": 1
    },
    {
      "x": -11,
      "y": 0,
      "z": 7,
      "name": "Rock_Runic_Brick",
      "rotation": 1
    },
    {
      "x": -11,
      "y": 1,
      "z": 7,
      "name": "Rock_Runic_Cobble",
      "rotation": 1
    },
    {
      "x": -11,
      "y": 2,
      "z": 7,
      "name": "Rock_Runic_Cobble",
      "rotation": 1
    },
    {
      "x": -11,
      "y": 3,
      "z": 7,
      "name": "Rock_Runic_Cobble",
      "rotation": 1
    },
    {
      "x": -11,
      "y": 4,
      "z": 7,
      "name": "Rock_Runic_Cobble",
      "rotation": 1
    },
    {
      "x": -11,
      "y": 5,
      "z": 7,
      "name": "Rock_Runic_Cobble_Half",
      "rotation": 1
    },
    {
      "x": -11,
      "y": 0,
      "z": 8,
      "name": "Rock_Runic_Brick",
      "rotation": 1
    },
    {
      "x": -11,
      "y": 1,
      "z": 8,
      "name": "Rock_Runic_Cobble",
      "rotation": 1
    },
    {
      "x": -11,
      "y": 2,
      "z": 8,
      "name": "Rock_Runic_Cobble",
      "rotation": 1
    },
    {
      "x": -11,
      "y": 3,
      "z": 8,
      "name": "Rock_Runic_Cobble",
      "rotation": 1
    },
    {
      "x": -11,
      "y": 4,
      "z": 8,
      "name": "Rock_Runic_Cobble",
      "rotation": 1
    },
    {
      "x": -11,
      "y": 5,
      "z": 8,
      "name": "Rock_Runic_Cobble_Half",
      "rotation": 1
    },
    {
      "x": -11,
      "y": 0,
      "z": 9,
      "name": "Rock_Runic_Brick",
      "rotation": 1
    },
    {
      "x": -11,
      "y": 1,
      "z": 9,
      "name": "Rock_Runic_Cobble",
      "rotation": 1
    },
    {
      "x": -11,
      "y": 2,
      "z": 9,
      "name": "Rock_Runic_Cobble",
